message
bash: cannot set terminal process group (-1): Inappropriate ioctl for device
bash: no job control in this shell
[2021-02-12 16:16:24 +0000] [20] [INFO] Starting gunicorn 19.9.0
[2021-02-12 16:16:24 +0000] [20] [INFO] Listening at: unix:/tmp/gunicorn.sock (20)
[2021-02-12 16:16:24 +0000] [20] [INFO] Using worker: gevent
[2021-02-12 16:16:24 +0000] [27] [INFO] Booting worker with pid: 27
[2021-02-12 16:16:25 +0000] [28] [INFO] Booting worker with pid: 28
[2021-02-12 16:16:25 +0000] [32] [INFO] Booting worker with pid: 32
[2021-02-12 16:16:25 +0000] [33] [INFO] Booting worker with pid: 33
Processing /opt/ml/code
"Collecting pandas (from -r requirements.txt (line 1))
  Downloading https://files.pythonhosted.org/packages/74/24/0cdbf8907e1e3bc5a8da03345c23cbed7044330bb8f73bb12e711a640a00/pandas-0.24.2-cp35-cp35m-manylinux1_x86_64.whl (10.0MB)"
Collecting numpy (from -r requirements.txt (line 2))
  Downloading https://files.pythonhosted.org/packages/b5/36/88723426b4ff576809fec7d73594fe17a35c27f8d01f93637637a29ae25b/numpy-1.18.5-cp35-cp35m-manylinux1_x86_64.whl (19.9MB)
"Collecting nltk (from -r requirements.txt (line 3))
  Downloading https://files.pythonhosted.org/packages/92/75/ce35194d8e3022203cca0d2f896dbb88689f9b3fce8e9f9cff942913519d/nltk-3.5.zip (1.4MB)"
"Collecting beautifulsoup4 (from -r requirements.txt (line 4))
  Downloading https://files.pythonhosted.org/packages/d1/41/e6495bd7d3781cee623ce23ea6ac73282a373088fcd0ddc809a047b18eae/beautifulsoup4-4.9.3-py3-none-any.whl (115kB)"
"Collecting html5lib (from -r requirements.txt (line 5))
  Downloading https://files.pythonhosted.org/packages/6c/dd/a834df6482147d48e225a49515aabc28974ad5a4ca3215c18a882565b028/html5lib-1.1-py2.py3-none-any.whl (112kB)"
"Collecting pytz>=2011k (from pandas->-r requirements.txt (line 1))
  Downloading https://files.pythonhosted.org/packages/70/94/784178ca5dd892a98f113cdd923372024dc04b8d40abe77ca76b5fb90ca6/pytz-2021.1-py2.py3-none-any.whl (510kB)"
Requirement already satisfied, skipping upgrade: python-dateutil>=2.5.0 in /usr/local/lib/python3.5/dist-packages (from pandas->-r requirements.txt (line 1)) (2.7.5)
Requirement already satisfied, skipping upgrade: click in /usr/local/lib/python3.5/dist-packages (from nltk->-r requirements.txt (line 3)) (7.0)
"Collecting joblib (from nltk->-r requirements.txt (line 3))
  Downloading https://files.pythonhosted.org/packages/28/5c/cf6a2b65a321c4a209efcdf64c2689efae2cb62661f8f6f4bb28547cf1bf/joblib-0.14.1-py2.py3-none-any.whl (294kB)"
Collecting regex (from nltk->-r requirements.txt (line 3))
Processing /opt/ml/code
"Collecting pandas (from -r requirements.txt (line 1))
  Downloading https://files.pythonhosted.org/packages/2e/e4/3447fed9ab29944333f48730ecff4dca92f0868c5b188d6ab2b2078e32c2/regex-2020.11.13.tar.gz (694kB)
  Using cached https://files.pythonhosted.org/packages/74/24/0cdbf8907e1e3bc5a8da03345c23cbed7044330bb8f73bb12e711a640a00/pandas-0.24.2-cp35-cp35m-manylinux1_x86_64.whl"
"Collecting tqdm (from nltk->-r requirements.txt (line 3))
  Downloading https://files.pythonhosted.org/packages/b3/db/dcda019790a8d989b8b0e7290f1c651a0aaef10bbe6af00032155e04858d/tqdm-4.56.2-py2.py3-none-any.whl (72kB)"
"Collecting soupsieve>1.2; python_version >= ""3.0"" (from beautifulsoup4->-r requirements.txt (line 4))
  Downloading https://files.pythonhosted.org/packages/02/fb/1c65691a9aeb7bd6ac2aa505b84cb8b49ac29c976411c6ab3659425e045f/soupsieve-2.1-py3-none-any.whl"
Requirement already satisfied, skipping upgrade: six>=1.9 in /usr/local/lib/python3.5/dist-packages (from html5lib->-r requirements.txt (line 5)) (1.11.0)
"Collecting webencodings (from html5lib->-r requirements.txt (line 5))
  Downloading https://files.pythonhosted.org/packages/f4/24/2a3e3df732393fed8b3ebf2ec078f05546de641fe1b667ee316ec1dcf3b7/webencodings-0.5.1-py2.py3-none-any.whl"
"Building wheels for collected packages: nltk, predict, regex
  Running setup.py bdist_wheel for nltk: started"
"Collecting numpy (from -r requirements.txt (line 2))
  Running setup.py bdist_wheel for nltk: finished with status 'done'
  Stored in directory: /root/.cache/pip/wheels/ae/8c/3f/b1fe0ba04555b08b57ab52ab7f86023639a526d8bc8d384306
  Running setup.py bdist_wheel for predict: started
  Using cached https://files.pythonhosted.org/packages/b5/36/88723426b4ff576809fec7d73594fe17a35c27f8d01f93637637a29ae25b/numpy-1.18.5-cp35-cp35m-manylinux1_x86_64.whl
  Running setup.py bdist_wheel for predict: finished with status 'done'
  Stored in directory: /tmp/pip-ephem-wheel-cache-bpkmfiie/wheels/35/24/16/37574d11bf9bde50616c67372a334f94fa8356bc7164af8ca3
  Running setup.py bdist_wheel for regex: started"
Collecting nltk (from -r requirements.txt (line 3))
"Collecting beautifulsoup4 (from -r requirements.txt (line 4))
  Using cached https://files.pythonhosted.org/packages/d1/41/e6495bd7d3781cee623ce23ea6ac73282a373088fcd0ddc809a047b18eae/beautifulsoup4-4.9.3-py3-none-any.whl"
"Collecting html5lib (from -r requirements.txt (line 5))
  Using cached https://files.pythonhosted.org/packages/6c/dd/a834df6482147d48e225a49515aabc28974ad5a4ca3215c18a882565b028/html5lib-1.1-py2.py3-none-any.whl"
"Collecting pytz>=2011k (from pandas->-r requirements.txt (line 1))
  Using cached https://files.pythonhosted.org/packages/70/94/784178ca5dd892a98f113cdd923372024dc04b8d40abe77ca76b5fb90ca6/pytz-2021.1-py2.py3-none-any.whl"
Requirement already satisfied, skipping upgrade: python-dateutil>=2.5.0 in /usr/local/lib/python3.5/dist-packages (from pandas->-r requirements.txt (line 1)) (2.7.5)
Collecting joblib (from nltk->-r requirements.txt (line 3))
  Using cached https://files.pythonhosted.org/packages/28/5c/cf6a2b65a321c4a209efcdf64c2689efae2cb62661f8f6f4bb28547cf1bf/joblib-0.14.1-py2.py3-none-any.whl
Requirement already satisfied, skipping upgrade: click in /usr/local/lib/python3.5/dist-packages (from nltk->-r requirements.txt (line 3)) (7.0)
"Collecting regex (from nltk->-r requirements.txt (line 3))
  Using cached https://files.pythonhosted.org/packages/2e/e4/3447fed9ab29944333f48730ecff4dca92f0868c5b188d6ab2b2078e32c2/regex-2020.11.13.tar.gz"
Collecting tqdm (from nltk->-r requirements.txt (line 3))
"Processing /opt/ml/code
  Using cached https://files.pythonhosted.org/packages/b3/db/dcda019790a8d989b8b0e7290f1c651a0aaef10bbe6af00032155e04858d/tqdm-4.56.2-py2.py3-none-any.whl"
"Collecting soupsieve>1.2; python_version >= ""3.0"" (from beautifulsoup4->-r requirements.txt (line 4))
  Using cached https://files.pythonhosted.org/packages/02/fb/1c65691a9aeb7bd6ac2aa505b84cb8b49ac29c976411c6ab3659425e045f/soupsieve-2.1-py3-none-any.whl"
Requirement already satisfied, skipping upgrade: six>=1.9 in /usr/local/lib/python3.5/dist-packages (from html5lib->-r requirements.txt (line 5)) (1.11.0)
"Collecting webencodings (from html5lib->-r requirements.txt (line 5))
  Using cached https://files.pythonhosted.org/packages/f4/24/2a3e3df732393fed8b3ebf2ec078f05546de641fe1b667ee316ec1dcf3b7/webencodings-0.5.1-py2.py3-none-any.whl"
"Building wheels for collected packages: predict, regex
  Running setup.py bdist_wheel for predict: started"
"Collecting pandas (from -r requirements.txt (line 1))
  Running setup.py bdist_wheel for predict: finished with status 'done'
  Stored in directory: /tmp/pip-ephem-wheel-cache-y7wm5rci/wheels/35/24/16/37574d11bf9bde50616c67372a334f94fa8356bc7164af8ca3
  Running setup.py bdist_wheel for regex: started"
  Using cached https://files.pythonhosted.org/packages/74/24/0cdbf8907e1e3bc5a8da03345c23cbed7044330bb8f73bb12e711a640a00/pandas-0.24.2-cp35-cp35m-manylinux1_x86_64.whl
Collecting numpy (from -r requirements.txt (line 2))
  Using cached https://files.pythonhosted.org/packages/b5/36/88723426b4ff576809fec7d73594fe17a35c27f8d01f93637637a29ae25b/numpy-1.18.5-cp35-cp35m-manylinux1_x86_64.whl
Collecting nltk (from -r requirements.txt (line 3))
"Collecting beautifulsoup4 (from -r requirements.txt (line 4))
  Using cached https://files.pythonhosted.org/packages/d1/41/e6495bd7d3781cee623ce23ea6ac73282a373088fcd0ddc809a047b18eae/beautifulsoup4-4.9.3-py3-none-any.whl"
"Collecting html5lib (from -r requirements.txt (line 5))
  Using cached https://files.pythonhosted.org/packages/6c/dd/a834df6482147d48e225a49515aabc28974ad5a4ca3215c18a882565b028/html5lib-1.1-py2.py3-none-any.whl"
Requirement already satisfied, skipping upgrade: python-dateutil>=2.5.0 in /usr/local/lib/python3.5/dist-packages (from pandas->-r requirements.txt (line 1)) (2.7.5)
Collecting pytz>=2011k (from pandas->-r requirements.txt (line 1))
"Processing /opt/ml/code
  Using cached https://files.pythonhosted.org/packages/70/94/784178ca5dd892a98f113cdd923372024dc04b8d40abe77ca76b5fb90ca6/pytz-2021.1-py2.py3-none-any.whl"
Collecting pandas (from -r requirements.txt (line 1))
Collecting joblib (from nltk->-r requirements.txt (line 3))
  Using cached https://files.pythonhosted.org/packages/28/5c/cf6a2b65a321c4a209efcdf64c2689efae2cb62661f8f6f4bb28547cf1bf/joblib-0.14.1-py2.py3-none-any.whl
"Collecting tqdm (from nltk->-r requirements.txt (line 3))
  Using cached https://files.pythonhosted.org/packages/b3/db/dcda019790a8d989b8b0e7290f1c651a0aaef10bbe6af00032155e04858d/tqdm-4.56.2-py2.py3-none-any.whl"
Requirement already satisfied, skipping upgrade: click in /usr/local/lib/python3.5/dist-packages (from nltk->-r requirements.txt (line 3)) (7.0)
"Collecting regex (from nltk->-r requirements.txt (line 3))
  Using cached https://files.pythonhosted.org/packages/74/24/0cdbf8907e1e3bc5a8da03345c23cbed7044330bb8f73bb12e711a640a00/pandas-0.24.2-cp35-cp35m-manylinux1_x86_64.whl"
  Using cached https://files.pythonhosted.org/packages/2e/e4/3447fed9ab29944333f48730ecff4dca92f0868c5b188d6ab2b2078e32c2/regex-2020.11.13.tar.gz
Collecting numpy (from -r requirements.txt (line 2))
"Collecting soupsieve>1.2; python_version >= ""3.0"" (from beautifulsoup4->-r requirements.txt (line 4))
  Using cached https://files.pythonhosted.org/packages/02/fb/1c65691a9aeb7bd6ac2aa505b84cb8b49ac29c976411c6ab3659425e045f/soupsieve-2.1-py3-none-any.whl"
"Collecting webencodings (from html5lib->-r requirements.txt (line 5))
  Using cached https://files.pythonhosted.org/packages/f4/24/2a3e3df732393fed8b3ebf2ec078f05546de641fe1b667ee316ec1dcf3b7/webencodings-0.5.1-py2.py3-none-any.whl"
Requirement already satisfied, skipping upgrade: six>=1.9 in /usr/local/lib/python3.5/dist-packages (from html5lib->-r requirements.txt (line 5)) (1.11.0)
"Building wheels for collected packages: predict, regex
  Running setup.py bdist_wheel for predict: started
  Running setup.py bdist_wheel for predict: finished with status 'done'
  Stored in directory: /tmp/pip-ephem-wheel-cache-dovhr65k/wheels/35/24/16/37574d11bf9bde50616c67372a334f94fa8356bc7164af8ca3
  Running setup.py bdist_wheel for regex: started"
  Using cached https://files.pythonhosted.org/packages/b5/36/88723426b4ff576809fec7d73594fe17a35c27f8d01f93637637a29ae25b/numpy-1.18.5-cp35-cp35m-manylinux1_x86_64.whl
Collecting nltk (from -r requirements.txt (line 3))
Collecting beautifulsoup4 (from -r requirements.txt (line 4))
"Processing /opt/ml/code
  Using cached https://files.pythonhosted.org/packages/d1/41/e6495bd7d3781cee623ce23ea6ac73282a373088fcd0ddc809a047b18eae/beautifulsoup4-4.9.3-py3-none-any.whl"
"Collecting html5lib (from -r requirements.txt (line 5))
  Using cached https://files.pythonhosted.org/packages/6c/dd/a834df6482147d48e225a49515aabc28974ad5a4ca3215c18a882565b028/html5lib-1.1-py2.py3-none-any.whl"
Requirement already satisfied, skipping upgrade: python-dateutil>=2.5.0 in /usr/local/lib/python3.5/dist-packages (from pandas->-r requirements.txt (line 1)) (2.7.5)
Collecting pytz>=2011k (from pandas->-r requirements.txt (line 1))
"Collecting pandas (from -r requirements.txt (line 1))
  Using cached https://files.pythonhosted.org/packages/70/94/784178ca5dd892a98f113cdd923372024dc04b8d40abe77ca76b5fb90ca6/pytz-2021.1-py2.py3-none-any.whl"
"Collecting tqdm (from nltk->-r requirements.txt (line 3))
  Using cached https://files.pythonhosted.org/packages/b3/db/dcda019790a8d989b8b0e7290f1c651a0aaef10bbe6af00032155e04858d/tqdm-4.56.2-py2.py3-none-any.whl"
Requirement already satisfied, skipping upgrade: click in /usr/local/lib/python3.5/dist-packages (from nltk->-r requirements.txt (line 3)) (7.0)
"Collecting joblib (from nltk->-r requirements.txt (line 3))
  Using cached https://files.pythonhosted.org/packages/28/5c/cf6a2b65a321c4a209efcdf64c2689efae2cb62661f8f6f4bb28547cf1bf/joblib-0.14.1-py2.py3-none-any.whl"
"Collecting regex (from nltk->-r requirements.txt (line 3))
  Running setup.py bdist_wheel for regex: finished with status 'done'
  Stored in directory: /root/.cache/pip/wheels/27/f6/66/a4243e485a0ebc73dc59033ae26c48e82526f77dbfe158ac59
  Using cached https://files.pythonhosted.org/packages/74/24/0cdbf8907e1e3bc5a8da03345c23cbed7044330bb8f73bb12e711a640a00/pandas-0.24.2-cp35-cp35m-manylinux1_x86_64.whl"
Successfully built nltk predict regex
"Installing collected packages: pytz, numpy, pandas, joblib, regex, tqdm, nltk, soupsieve, beautifulsoup4, webencodings, html5lib, predict
  Found existing installation: numpy 1.15.4"
"  Running setup.py bdist_wheel for regex: finished with status 'done'
  Stored in directory: /root/.cache/pip/wheels/27/f6/66/a4243e485a0ebc73dc59033ae26c48e82526f77dbfe158ac59"
"Successfully built predict regex
    Uninstalling numpy-1.15.4:"
Installing collected packages: pytz, numpy, pandas, joblib, regex, tqdm, nltk, soupsieve, beautifulsoup4, webencodings, html5lib, predict
"Collecting soupsieve>1.2; python_version >= ""3.0"" (from beautifulsoup4->-r requirements.txt (line 4))
  Found existing installation: numpy 1.15.4
    Can't uninstall 'numpy'. No files were found to uninstall.
  Using cached https://files.pythonhosted.org/packages/02/fb/1c65691a9aeb7bd6ac2aa505b84cb8b49ac29c976411c6ab3659425e045f/soupsieve-2.1-py3-none-any.whl"
Collecting numpy (from -r requirements.txt (line 2))
Requirement already satisfied, skipping upgrade: six>=1.9 in /usr/local/lib/python3.5/dist-packages (from html5lib->-r requirements.txt (line 5)) (1.11.0)
"Collecting webencodings (from html5lib->-r requirements.txt (line 5))
  Using cached https://files.pythonhosted.org/packages/f4/24/2a3e3df732393fed8b3ebf2ec078f05546de641fe1b667ee316ec1dcf3b7/webencodings-0.5.1-py2.py3-none-any.whl"
"Building wheels for collected packages: predict
  Running setup.py bdist_wheel for predict: started"
"  Running setup.py bdist_wheel for predict: finished with status 'done'
  Stored in directory: /tmp/pip-ephem-wheel-cache-5w9k85lk/wheels/35/24/16/37574d11bf9bde50616c67372a334f94fa8356bc7164af8ca3"
Successfully built predict
"      Successfully uninstalled numpy-1.15.4
  Using cached https://files.pythonhosted.org/packages/b5/36/88723426b4ff576809fec7d73594fe17a35c27f8d01f93637637a29ae25b/numpy-1.18.5-cp35-cp35m-manylinux1_x86_64.whl"
"Could not install packages due to an EnvironmentError: [Errno 2] No such file or directory: '/usr/local/lib/python3.5/dist-packages/numpy-1.15.4.dist-info/METADATA'
"
You are using pip version 18.1, however version 20.3.4 is available.
You should consider upgrading via the 'pip install --upgrade pip' command.
Processing /opt/ml/code
[2021-02-12 16:17:46 +0000] [28] [ERROR] Error handling request /ping
"Traceback (most recent call last):
  File ""/usr/local/lib/python3.5/dist-packages/gunicorn/workers/base_async.py"", line 56, in handle
    self.handle_request(listener_name, req, client, addr)
  File ""/usr/local/lib/python3.5/dist-packages/gunicorn/workers/ggevent.py"", line 160, in handle_request
    addr)
  File ""/usr/local/lib/python3.5/dist-packages/gunicorn/workers/base_async.py"", line 107, in handle_request
    respiter = self.wsgi(environ, resp.start_response)
  File ""/usr/local/lib/python3.5/dist-packages/sagemaker_pytorch_container/serving.py"", line 103, in main
    user_module = modules.import_module(serving_env.module_dir, serving_env.module_name)
  File ""/usr/local/lib/python3.5/dist-packages/sagemaker_containers/_modules.py"", line 246, in import_module
    install(_env.code_dir)
  File ""/usr/local/lib/python3.5/dist-packages/sagemaker_containers/_modules.py"", line 109, in install
    _process.check_error(shlex.split(cmd), _errors.InstallModuleError, cwd=path, capture_error=capture_error)
  File ""/usr/local/lib/python3.5/dist-packages/sagemaker_containers/_process.py"", line 43, in check_error
    raise error_class(return_code=return_code, cmd=' '.join(cmd), output=stderr)"
sagemaker_containers._errors.InstallModuleError: InstallModuleError:
"Command ""/usr/bin/python -m pip install -U . -r requirements.txt"""
"10.32.0.2 - - [12/Feb/2021:16:17:46 +0000] ""GET /ping HTTP/1.1"" 500 141 ""-"" ""AHC/2.0"""
Collecting nltk (from -r requirements.txt (line 3))
Collecting pandas (from -r requirements.txt (line 1))
"Collecting beautifulsoup4 (from -r requirements.txt (line 4))
  Using cached https://files.pythonhosted.org/packages/d1/41/e6495bd7d3781cee623ce23ea6ac73282a373088fcd0ddc809a047b18eae/beautifulsoup4-4.9.3-py3-none-any.whl"
"Collecting html5lib (from -r requirements.txt (line 5))
  Using cached https://files.pythonhosted.org/packages/6c/dd/a834df6482147d48e225a49515aabc28974ad5a4ca3215c18a882565b028/html5lib-1.1-py2.py3-none-any.whl"
Requirement already satisfied, skipping upgrade: python-dateutil>=2.5.0 in /usr/local/lib/python3.5/dist-packages (from pandas->-r requirements.txt (line 1)) (2.7.5)
Requirement already satisfied, skipping upgrade: pytz>=2011k in /usr/local/lib/python3.5/dist-packages (from pandas->-r requirements.txt (line 1)) (2021.1)
Collecting joblib (from nltk->-r requirements.txt (line 3))
  Using cached https://files.pythonhosted.org/packages/28/5c/cf6a2b65a321c4a209efcdf64c2689efae2cb62661f8f6f4bb28547cf1bf/joblib-0.14.1-py2.py3-none-any.whl
Requirement already satisfied, skipping upgrade: click in /usr/local/lib/python3.5/dist-packages (from nltk->-r requirements.txt (line 3)) (7.0)
"Collecting tqdm (from nltk->-r requirements.txt (line 3))
  Using cached https://files.pythonhosted.org/packages/74/24/0cdbf8907e1e3bc5a8da03345c23cbed7044330bb8f73bb12e711a640a00/pandas-0.24.2-cp35-cp35m-manylinux1_x86_64.whl
  Using cached https://files.pythonhosted.org/packages/b3/db/dcda019790a8d989b8b0e7290f1c651a0aaef10bbe6af00032155e04858d/tqdm-4.56.2-py2.py3-none-any.whl"
Collecting regex (from nltk->-r requirements.txt (line 3))
Requirement already up-to-date: numpy in /usr/local/lib/python3.5/dist-packages (from -r requirements.txt (line 2)) (1.18.5)
Collecting nltk (from -r requirements.txt (line 3))
"Collecting soupsieve>1.2; python_version >= ""3.0"" (from beautifulsoup4->-r requirements.txt (line 4))"
"Collecting beautifulsoup4 (from -r requirements.txt (line 4))
  Using cached https://files.pythonhosted.org/packages/02/fb/1c65691a9aeb7bd6ac2aa505b84cb8b49ac29c976411c6ab3659425e045f/soupsieve-2.1-py3-none-any.whl
  Using cached https://files.pythonhosted.org/packages/d1/41/e6495bd7d3781cee623ce23ea6ac73282a373088fcd0ddc809a047b18eae/beautifulsoup4-4.9.3-py3-none-any.whl"
"Collecting webencodings (from html5lib->-r requirements.txt (line 5))
  Using cached https://files.pythonhosted.org/packages/f4/24/2a3e3df732393fed8b3ebf2ec078f05546de641fe1b667ee316ec1dcf3b7/webencodings-0.5.1-py2.py3-none-any.whl"
Collecting html5lib (from -r requirements.txt (line 5))
Requirement already satisfied, skipping upgrade: six>=1.9 in /usr/local/lib/python3.5/dist-packages (from html5lib->-r requirements.txt (line 5)) (1.11.0)
"Building wheels for collected packages: predict
  Running setup.py bdist_wheel for predict: started
  Using cached https://files.pythonhosted.org/packages/6c/dd/a834df6482147d48e225a49515aabc28974ad5a4ca3215c18a882565b028/html5lib-1.1-py2.py3-none-any.whl"
Requirement already satisfied, skipping upgrade: pytz>=2011k in /usr/local/lib/python3.5/dist-packages (from pandas->-r requirements.txt (line 1)) (2021.1)
Requirement already satisfied, skipping upgrade: python-dateutil>=2.5.0 in /usr/local/lib/python3.5/dist-packages (from pandas->-r requirements.txt (line 1)) (2.7.5)
Requirement already satisfied, skipping upgrade: click in /usr/local/lib/python3.5/dist-packages (from nltk->-r requirements.txt (line 3)) (7.0)
Collecting tqdm (from nltk->-r requirements.txt (line 3))
  Using cached https://files.pythonhosted.org/packages/b3/db/dcda019790a8d989b8b0e7290f1c651a0aaef10bbe6af00032155e04858d/tqdm-4.56.2-py2.py3-none-any.whl
"Collecting regex (from nltk->-r requirements.txt (line 3))
  Running setup.py bdist_wheel for predict: finished with status 'done'
  Stored in directory: /tmp/pip-ephem-wheel-cache-lomy91va/wheels/35/24/16/37574d11bf9bde50616c67372a334f94fa8356bc7164af8ca3"
Successfully built predict
Processing /opt/ml/code
"Could not install packages due to an EnvironmentError: [Errno 2] No such file or directory: '/usr/local/lib/python3.5/dist-packages/numpy-1.15.4.dist-info/METADATA'
"
You are using pip version 18.1, however version 20.3.4 is available.
You should consider upgrading via the 'pip install --upgrade pip' command.
[2021-02-12 16:17:52 +0000] [33] [ERROR] Error handling request /ping
"Traceback (most recent call last):
  File ""/usr/local/lib/python3.5/dist-packages/gunicorn/workers/base_async.py"", line 56, in handle
    self.handle_request(listener_name, req, client, addr)
  File ""/usr/local/lib/python3.5/dist-packages/gunicorn/workers/ggevent.py"", line 160, in handle_request
    addr)
  File ""/usr/local/lib/python3.5/dist-packages/gunicorn/workers/base_async.py"", line 107, in handle_request
    respiter = self.wsgi(environ, resp.start_response)
  File ""/usr/local/lib/python3.5/dist-packages/sagemaker_pytorch_container/serving.py"", line 103, in main
    user_module = modules.import_module(serving_env.module_dir, serving_env.module_name)
  File ""/usr/local/lib/python3.5/dist-packages/sagemaker_containers/_modules.py"", line 246, in import_module
    install(_env.code_dir)
  File ""/usr/local/lib/python3.5/dist-packages/sagemaker_containers/_modules.py"", line 109, in install
    _process.check_error(shlex.split(cmd), _errors.InstallModuleError, cwd=path, capture_error=capture_error)
  File ""/usr/local/lib/python3.5/dist-packages/sagemaker_containers/_process.py"", line 43, in check_error
    raise error_class(return_code=return_code, cmd=' '.join(cmd), output=stderr)"
sagemaker_containers._errors.InstallModuleError: InstallModuleError:
"Command ""/usr/bin/python -m pip install -U . -r requirements.txt"""
"10.32.0.2 - - [12/Feb/2021:16:17:52 +0000] ""GET /ping HTTP/1.1"" 500 141 ""-"" ""AHC/2.0"""
Collecting pandas (from -r requirements.txt (line 1))
"Collecting joblib (from nltk->-r requirements.txt (line 3))
  Using cached https://files.pythonhosted.org/packages/28/5c/cf6a2b65a321c4a209efcdf64c2689efae2cb62661f8f6f4bb28547cf1bf/joblib-0.14.1-py2.py3-none-any.whl
  Using cached https://files.pythonhosted.org/packages/74/24/0cdbf8907e1e3bc5a8da03345c23cbed7044330bb8f73bb12e711a640a00/pandas-0.24.2-cp35-cp35m-manylinux1_x86_64.whl"
"Collecting soupsieve>1.2; python_version >= ""3.0"" (from beautifulsoup4->-r requirements.txt (line 4))
  Using cached https://files.pythonhosted.org/packages/02/fb/1c65691a9aeb7bd6ac2aa505b84cb8b49ac29c976411c6ab3659425e045f/soupsieve-2.1-py3-none-any.whl"
Requirement already satisfied, skipping upgrade: six>=1.9 in /usr/local/lib/python3.5/dist-packages (from html5lib->-r requirements.txt (line 5)) (1.11.0)
"Collecting webencodings (from html5lib->-r requirements.txt (line 5))
  Using cached https://files.pythonhosted.org/packages/f4/24/2a3e3df732393fed8b3ebf2ec078f05546de641fe1b667ee316ec1dcf3b7/webencodings-0.5.1-py2.py3-none-any.whl"
"Building wheels for collected packages: predict
  Running setup.py bdist_wheel for predict: started"
"  Running setup.py bdist_wheel for predict: finished with status 'done'
  Stored in directory: /tmp/pip-ephem-wheel-cache-ucld0n6h/wheels/35/24/16/37574d11bf9bde50616c67372a334f94fa8356bc7164af8ca3"
Successfully built predict
Installing collected packages: pandas, tqdm, regex, joblib, nltk, soupsieve, beautifulsoup4, webencodings, html5lib, predict
Requirement already up-to-date: numpy in /usr/local/lib/python3.5/dist-packages (from -r requirements.txt (line 2)) (1.18.5)
Collecting nltk (from -r requirements.txt (line 3))
Collecting beautifulsoup4 (from -r requirements.txt (line 4))
  Using cached https://files.pythonhosted.org/packages/d1/41/e6495bd7d3781cee623ce23ea6ac73282a373088fcd0ddc809a047b18eae/beautifulsoup4-4.9.3-py3-none-any.whl
"Collecting html5lib (from -r requirements.txt (line 5))
  Using cached https://files.pythonhosted.org/packages/6c/dd/a834df6482147d48e225a49515aabc28974ad5a4ca3215c18a882565b028/html5lib-1.1-py2.py3-none-any.whl"
Requirement already satisfied, skipping upgrade: python-dateutil>=2.5.0 in /usr/local/lib/python3.5/dist-packages (from pandas->-r requirements.txt (line 1)) (2.7.5)
Requirement already satisfied, skipping upgrade: pytz>=2011k in /usr/local/lib/python3.5/dist-packages (from pandas->-r requirements.txt (line 1)) (2021.1)
Requirement already satisfied, skipping upgrade: click in /usr/local/lib/python3.5/dist-packages (from nltk->-r requirements.txt (line 3)) (7.0)
Requirement already satisfied, skipping upgrade: joblib in /usr/local/lib/python3.5/dist-packages (from nltk->-r requirements.txt (line 3)) (0.14.1)
Requirement already satisfied, skipping upgrade: regex in /usr/local/lib/python3.5/dist-packages (from nltk->-r requirements.txt (line 3)) (2020.11.13)
Requirement already satisfied, skipping upgrade: tqdm in /usr/local/lib/python3.5/dist-packages (from nltk->-r requirements.txt (line 3)) (4.56.2)
Processing /opt/ml/code
"Requirement already satisfied, skipping upgrade: soupsieve>1.2; python_version >= ""3.0"" in /usr/local/lib/python3.5/dist-packages (from beautifulsoup4->-r requirements.txt (line 4)) (2.1)"
Requirement already satisfied, skipping upgrade: six>=1.9 in /usr/local/lib/python3.5/dist-packages (from html5lib->-r requirements.txt (line 5)) (1.11.0)
"Collecting webencodings (from html5lib->-r requirements.txt (line 5))
  Using cached https://files.pythonhosted.org/packages/f4/24/2a3e3df732393fed8b3ebf2ec078f05546de641fe1b667ee316ec1dcf3b7/webencodings-0.5.1-py2.py3-none-any.whl"
"Building wheels for collected packages: predict
  Running setup.py bdist_wheel for predict: started"
"Successfully installed beautifulsoup4-4.9.3 html5lib-1.1 joblib-0.14.1 nltk-3.5 numpy-1.18.5 pandas-0.24.2 predict-1.0.0 pytz-2021.1 regex-2020.11.13 soupsieve-2.1 tqdm-4.56.2 webencodings-0.5.1
  Running setup.py bdist_wheel for regex: finished with status 'done'
  Stored in directory: /root/.cache/pip/wheels/27/f6/66/a4243e485a0ebc73dc59033ae26c48e82526f77dbfe158ac59"
Successfully built predict regex
You are using pip version 18.1, however version 20.3.4 is available.
You should consider upgrading via the 'pip install --upgrade pip' command.
"Could not install packages due to an EnvironmentError: [Errno 2] No such file or directory: '/usr/local/lib/python3.5/dist-packages/numpy-1.15.4.dist-info/METADATA'
"
You are using pip version 18.1, however version 20.3.4 is available.
"You should consider upgrading via the 'pip install --upgrade pip' command.
  Running setup.py bdist_wheel for predict: finished with status 'done'
  Stored in directory: /tmp/pip-ephem-wheel-cache-0vls59rq/wheels/35/24/16/37574d11bf9bde50616c67372a334f94fa8356bc7164af8ca3"
Successfully built predict
"Installing collected packages: pandas, nltk, beautifulsoup4, webencodings, html5lib, predict
  Found existing installation: pandas 0.24.2"
Requirement already up-to-date: pandas in /usr/local/lib/python3.5/dist-packages (from -r requirements.txt (line 1)) (0.24.2)
Loading model.
model_info: {'hidden_dim': 200, 'vocab_size': 5000, 'embedding_dim': 32}
Done loading model.
"10.32.0.2 - - [12/Feb/2021:16:17:58 +0000] ""GET /ping HTTP/1.1"" 200 0 ""-"" ""AHC/2.0"""
[2021-02-12 16:17:58 +0000] [33] [ERROR] Error handling request /ping
"Traceback (most recent call last):
  File ""/usr/local/lib/python3.5/dist-packages/gunicorn/workers/base_async.py"", line 56, in handle
    self.handle_request(listener_name, req, client, addr)
  File ""/usr/local/lib/python3.5/dist-packages/gunicorn/workers/ggevent.py"", line 160, in handle_request
    addr)
  File ""/usr/local/lib/python3.5/dist-packages/gunicorn/workers/base_async.py"", line 107, in handle_request
    respiter = self.wsgi(environ, resp.start_response)
  File ""/usr/local/lib/python3.5/dist-packages/sagemaker_pytorch_container/serving.py"", line 103, in main
    user_module = modules.import_module(serving_env.module_dir, serving_env.module_name)
  File ""/usr/local/lib/python3.5/dist-packages/sagemaker_containers/_modules.py"", line 246, in import_module
    install(_env.code_dir)
  File ""/usr/local/lib/python3.5/dist-packages/sagemaker_containers/_modules.py"", line 109, in install
    _process.check_error(shlex.split(cmd), _errors.InstallModuleError, cwd=path, capture_error=capture_error)
  File ""/usr/local/lib/python3.5/dist-packages/sagemaker_containers/_process.py"", line 43, in check_error
    raise error_class(return_code=return_code, cmd=' '.join(cmd), output=stderr)"
sagemaker_containers._errors.InstallModuleError: InstallModuleError:
"Command ""/usr/bin/python -m pip install -U . -r requirements.txt"""
"10.32.0.2 - - [12/Feb/2021:16:17:58 +0000] ""GET /ping HTTP/1.1"" 500 141 ""-"" ""AHC/2.0""
    Uninstalling pandas-0.24.2:"
Successfully installed beautifulsoup4-4.9.3 html5lib-1.1 joblib-0.14.1 nltk-3.5 numpy-1.18.5 pandas-0.24.2 predict-1.0.0 pytz-2021.1 regex-2020.11.13 soupsieve-2.1 tqdm-4.56.2 webencodings-0.5.1
Requirement already up-to-date: numpy in /usr/local/lib/python3.5/dist-packages (from -r requirements.txt (line 2)) (1.18.5)
Requirement already up-to-date: nltk in /usr/local/lib/python3.5/dist-packages (from -r requirements.txt (line 3)) (3.5)
You are using pip version 18.1, however version 20.3.4 is available.
You should consider upgrading via the 'pip install --upgrade pip' command.
Requirement already up-to-date: beautifulsoup4 in /usr/local/lib/python3.5/dist-packages (from -r requirements.txt (line 4)) (4.9.3)
Requirement already up-to-date: html5lib in /usr/local/lib/python3.5/dist-packages (from -r requirements.txt (line 5)) (1.1)
Requirement already satisfied, skipping upgrade: python-dateutil>=2.5.0 in /usr/local/lib/python3.5/dist-packages (from pandas->-r requirements.txt (line 1)) (2.7.5)
Requirement already satisfied, skipping upgrade: pytz>=2011k in /usr/local/lib/python3.5/dist-packages (from pandas->-r requirements.txt (line 1)) (2021.1)
Requirement already satisfied, skipping upgrade: regex in /usr/local/lib/python3.5/dist-packages (from nltk->-r requirements.txt (line 3)) (2020.11.13)
Requirement already satisfied, skipping upgrade: joblib in /usr/local/lib/python3.5/dist-packages (from nltk->-r requirements.txt (line 3)) (0.14.1)
Requirement already satisfied, skipping upgrade: click in /usr/local/lib/python3.5/dist-packages (from nltk->-r requirements.txt (line 3)) (7.0)
Requirement already satisfied, skipping upgrade: tqdm in /usr/local/lib/python3.5/dist-packages (from nltk->-r requirements.txt (line 3)) (4.56.2)
"Requirement already satisfied, skipping upgrade: soupsieve>1.2; python_version >= ""3.0"" in /usr/local/lib/python3.5/dist-packages (from beautifulsoup4->-r requirements.txt (line 4)) (2.1)"
Requirement already satisfied, skipping upgrade: six>=1.9 in /usr/local/lib/python3.5/dist-packages (from html5lib->-r requirements.txt (line 5)) (1.11.0)
Requirement already satisfied, skipping upgrade: webencodings in /usr/local/lib/python3.5/dist-packages (from html5lib->-r requirements.txt (line 5)) (0.5.1)
"Building wheels for collected packages: predict
  Running setup.py bdist_wheel for predict: started"
[2021-02-12 16:17:59 +0000] [27] [ERROR] Error handling request /ping
"Traceback (most recent call last):
  File ""/usr/local/lib/python3.5/dist-packages/sagemaker_containers/_modules.py"", line 248, in import_module
    module = importlib.import_module(name)
  File ""/usr/lib/python3.5/importlib/__init__.py"", line 126, in import_module
    return _bootstrap._gcd_import(name[level:], package, level)
  File ""<frozen importlib._bootstrap>"", line 986, in _gcd_import
  File ""<frozen importlib._bootstrap>"", line 969, in _find_and_load
  File ""<frozen importlib._bootstrap>"", line 958, in _find_and_load_unlocked
  File ""<frozen importlib._bootstrap>"", line 673, in _load_unlocked
  File ""<frozen importlib._bootstrap_external>"", line 665, in exec_module
  File ""<frozen importlib._bootstrap>"", line 222, in _call_with_frames_removed
  File ""/usr/local/lib/python3.5/dist-packages/predict.py"", line 7, in <module>
    import pandas as pd
  File ""/usr/local/lib/python3.5/dist-packages/pandas/__init__.py"", line 42, in <module>
  File ""/usr/local/lib/python3.5/dist-packages/pandas/core/api.py"", line 7, in <module>
    from pandas.core.arrays.integer import (
  File ""/usr/local/lib/python3.5/dist-packages/pandas/core/arrays/__init__.py"", line 1, in <module>
    from .array_ import array  # noqa
  File ""/usr/local/lib/python3.5/dist-packages/pandas/core/arrays/array_.py"", line 3, in <module>
    from pandas.core.dtypes.common import (
  File ""/usr/local/lib/python3.5/dist-packages/pandas/core/dtypes/common.py"", line 6, in <module>
    from pandas._libs import algos, lib"
"ImportError: cannot import name 'algos'
"
"During handling of the above exception, another exception occurred:
"
"Traceback (most recent call last):
  File ""/usr/local/lib/python3.5/dist-packages/gunicorn/workers/base_async.py"", line 56, in handle
    self.handle_request(listener_name, req, client, addr)
  File ""/usr/local/lib/python3.5/dist-packages/gunicorn/workers/ggevent.py"", line 160, in handle_request
    addr)
  File ""/usr/local/lib/python3.5/dist-packages/gunicorn/workers/base_async.py"", line 107, in handle_request
    respiter = self.wsgi(environ, resp.start_response)
  File ""/usr/local/lib/python3.5/dist-packages/sagemaker_pytorch_container/serving.py"", line 103, in main
    user_module = modules.import_module(serving_env.module_dir, serving_env.module_name)
  File ""/usr/local/lib/python3.5/dist-packages/sagemaker_containers/_modules.py"", line 253, in import_module
    six.reraise(_errors.ImportModuleError, _errors.ImportModuleError(e), sys.exc_info()[2])
  File ""/usr/local/lib/python3.5/dist-packages/six.py"", line 692, in reraise
    raise value.with_traceback(tb)
  File ""/usr/local/lib/python3.5/dist-packages/sagemaker_containers/_modules.py"", line 248, in import_module
    module = importlib.import_module(name)
  File ""/usr/lib/python3.5/importlib/__init__.py"", line 126, in import_module
    return _bootstrap._gcd_import(name[level:], package, level)
  File ""<frozen importlib._bootstrap>"", line 986, in _gcd_import
  File ""<frozen importlib._bootstrap>"", line 969, in _find_and_load
  File ""<frozen importlib._bootstrap>"", line 958, in _find_and_load_unlocked
  File ""<frozen importlib._bootstrap>"", line 673, in _load_unlocked
  File ""<frozen importlib._bootstrap_external>"", line 665, in exec_module
  File ""<frozen importlib._bootstrap>"", line 222, in _call_with_frames_removed
  File ""/usr/local/lib/python3.5/dist-packages/predict.py"", line 7, in <module>
    import pandas as pd
  File ""/usr/local/lib/python3.5/dist-packages/pandas/__init__.py"", line 42, in <module>
  File ""/usr/local/lib/python3.5/dist-packages/pandas/core/api.py"", line 7, in <module>
    from pandas.core.arrays.integer import (
  File ""/usr/local/lib/python3.5/dist-packages/pandas/core/arrays/__init__.py"", line 1, in <module>
    from .array_ import array  # noqa
  File ""/usr/local/lib/python3.5/dist-packages/pandas/core/arrays/array_.py"", line 3, in <module>
    from pandas.core.dtypes.common import (
  File ""/usr/local/lib/python3.5/dist-packages/pandas/core/dtypes/common.py"", line 6, in <module>
    from pandas._libs import algos, lib"
sagemaker_containers._errors.ImportModuleError: cannot import name 'algos'
"10.32.0.2 - - [12/Feb/2021:16:17:59 +0000] ""GET /ping HTTP/1.1"" 500 141 ""-"" ""AHC/2.0""
      Successfully uninstalled pandas-0.24.2
  Running setup.py bdist_wheel for predict: finished with status 'done'
  Stored in directory: /tmp/pip-ephem-wheel-cache-fzh5e86f/wheels/35/24/16/37574d11bf9bde50616c67372a334f94fa8356bc7164af8ca3"
Successfully built predict
"Installing collected packages: predict
  Found existing installation: predict 1.0.0"
"    Uninstalling predict-1.0.0:
      Successfully uninstalled predict-1.0.0"
Successfully installed predict-1.0.0
You are using pip version 18.1, however version 20.3.4 is available.
You should consider upgrading via the 'pip install --upgrade pip' command.
Loading model.
model_info: {'hidden_dim': 200, 'vocab_size': 5000, 'embedding_dim': 32}
Done loading model.
"10.32.0.2 - - [12/Feb/2021:16:18:00 +0000] ""GET /ping HTTP/1.1"" 200 0 ""-"" ""AHC/2.0"""
Processing /opt/ml/code
Successfully installed beautifulsoup4-4.9.3 html5lib-1.1 joblib-0.14.1 nltk-3.5 pandas-0.24.2 predict-1.0.0 regex-2020.11.13 soupsieve-2.1 tqdm-4.56.2 webencodings-0.5.1
You are using pip version 18.1, however version 20.3.4 is available.
You should consider upgrading via the 'pip install --upgrade pip' command.
[2021-02-12 16:18:02 +0000] [28] [ERROR] Error handling request /ping
"Traceback (most recent call last):
  File ""/usr/local/lib/python3.5/dist-packages/sagemaker_containers/_modules.py"", line 248, in import_module
    module = importlib.import_module(name)
  File ""/usr/lib/python3.5/importlib/__init__.py"", line 126, in import_module
    return _bootstrap._gcd_import(name[level:], package, level)
  File ""<frozen importlib._bootstrap>"", line 986, in _gcd_import
  File ""<frozen importlib._bootstrap>"", line 969, in _find_and_load
  File ""<frozen importlib._bootstrap>"", line 958, in _find_and_load_unlocked
  File ""<frozen importlib._bootstrap>"", line 673, in _load_unlocked
  File ""<frozen importlib._bootstrap_external>"", line 665, in exec_module
  File ""<frozen importlib._bootstrap>"", line 222, in _call_with_frames_removed
  File ""/usr/local/lib/python3.5/dist-packages/predict.py"", line 7, in <module>
    import pandas as pd
  File ""/usr/local/lib/python3.5/dist-packages/pandas/__init__.py"", line 42, in <module>
    from pandas.core.api import *
  File ""/usr/local/lib/python3.5/dist-packages/pandas/core/api.py"", line 7, in <module>
    from pandas.core.arrays.integer import (
  File ""/usr/local/lib/python3.5/dist-packages/pandas/core/arrays/__init__.py"", line 2, in <module>
    from .base import (ExtensionArray,    # noqa
  File ""/usr/local/lib/python3.5/dist-packages/pandas/core/arrays/base.py"", line 13, in <module>
    from pandas.compat.numpy import function as nv
  File ""/usr/local/lib/python3.5/dist-packages/pandas/compat/numpy/function.py"", line 25, in <module>
    from pandas.util._validators import ("
"ImportError: No module named 'pandas.util'
"
"During handling of the above exception, another exception occurred:
"
"Traceback (most recent call last):
  File ""/usr/local/lib/python3.5/dist-packages/gunicorn/workers/base_async.py"", line 56, in handle
    self.handle_request(listener_name, req, client, addr)
  File ""/usr/local/lib/python3.5/dist-packages/gunicorn/workers/ggevent.py"", line 160, in handle_request
    addr)
  File ""/usr/local/lib/python3.5/dist-packages/gunicorn/workers/base_async.py"", line 107, in handle_request
    respiter = self.wsgi(environ, resp.start_response)
  File ""/usr/local/lib/python3.5/dist-packages/sagemaker_pytorch_container/serving.py"", line 103, in main
    user_module = modules.import_module(serving_env.module_dir, serving_env.module_name)
  File ""/usr/local/lib/python3.5/dist-packages/sagemaker_containers/_modules.py"", line 253, in import_module
    six.reraise(_errors.ImportModuleError, _errors.ImportModuleError(e), sys.exc_info()[2])
  File ""/usr/local/lib/python3.5/dist-packages/six.py"", line 692, in reraise
    raise value.with_traceback(tb)
  File ""/usr/local/lib/python3.5/dist-packages/sagemaker_containers/_modules.py"", line 248, in import_module
    module = importlib.import_module(name)
  File ""/usr/lib/python3.5/importlib/__init__.py"", line 126, in import_module
    return _bootstrap._gcd_import(name[level:], package, level)
  File ""<frozen importlib._bootstrap>"", line 986, in _gcd_import
  File ""<frozen importlib._bootstrap>"", line 969, in _find_and_load
  File ""<frozen importlib._bootstrap>"", line 958, in _find_and_load_unlocked
  File ""<frozen importlib._bootstrap>"", line 673, in _load_unlocked
  File ""<frozen importlib._bootstrap_external>"", line 665, in exec_module
  File ""<frozen importlib._bootstrap>"", line 222, in _call_with_frames_removed
  File ""/usr/local/lib/python3.5/dist-packages/predict.py"", line 7, in <module>
    import pandas as pd
  File ""/usr/local/lib/python3.5/dist-packages/pandas/__init__.py"", line 42, in <module>
    from pandas.core.api import *
  File ""/usr/local/lib/python3.5/dist-packages/pandas/core/api.py"", line 7, in <module>
    from pandas.core.arrays.integer import (
  File ""/usr/local/lib/python3.5/dist-packages/pandas/core/arrays/__init__.py"", line 2, in <module>
    from .base import (ExtensionArray,    # noqa
  File ""/usr/local/lib/python3.5/dist-packages/pandas/core/arrays/base.py"", line 13, in <module>
    from pandas.compat.numpy import function as nv
  File ""/usr/local/lib/python3.5/dist-packages/pandas/compat/numpy/function.py"", line 25, in <module>
    from pandas.util._validators import ("
sagemaker_containers._errors.ImportModuleError: No module named 'pandas.util'
"10.32.0.2 - - [12/Feb/2021:16:18:02 +0000] ""GET /ping HTTP/1.1"" 500 141 ""-"" ""AHC/2.0"""
Requirement already up-to-date: pandas in /usr/local/lib/python3.5/dist-packages (from -r requirements.txt (line 1)) (0.24.2)
Requirement already up-to-date: numpy in /usr/local/lib/python3.5/dist-packages (from -r requirements.txt (line 2)) (1.18.5)
Requirement already up-to-date: nltk in /usr/local/lib/python3.5/dist-packages (from -r requirements.txt (line 3)) (3.5)
Requirement already up-to-date: beautifulsoup4 in /usr/local/lib/python3.5/dist-packages (from -r requirements.txt (line 4)) (4.9.3)
Requirement already up-to-date: html5lib in /usr/local/lib/python3.5/dist-packages (from -r requirements.txt (line 5)) (1.1)
Requirement already satisfied, skipping upgrade: pytz>=2011k in /usr/local/lib/python3.5/dist-packages (from pandas->-r requirements.txt (line 1)) (2021.1)
Requirement already satisfied, skipping upgrade: python-dateutil>=2.5.0 in /usr/local/lib/python3.5/dist-packages (from pandas->-r requirements.txt (line 1)) (2.7.5)
Requirement already satisfied, skipping upgrade: click in /usr/local/lib/python3.5/dist-packages (from nltk->-r requirements.txt (line 3)) (7.0)
Requirement already satisfied, skipping upgrade: tqdm in /usr/local/lib/python3.5/dist-packages (from nltk->-r requirements.txt (line 3)) (4.56.2)
Requirement already satisfied, skipping upgrade: regex in /usr/local/lib/python3.5/dist-packages (from nltk->-r requirements.txt (line 3)) (2020.11.13)
Requirement already satisfied, skipping upgrade: joblib in /usr/local/lib/python3.5/dist-packages (from nltk->-r requirements.txt (line 3)) (0.14.1)
"Requirement already satisfied, skipping upgrade: soupsieve>1.2; python_version >= ""3.0"" in /usr/local/lib/python3.5/dist-packages (from beautifulsoup4->-r requirements.txt (line 4)) (2.1)"
Requirement already satisfied, skipping upgrade: six>=1.9 in /usr/local/lib/python3.5/dist-packages (from html5lib->-r requirements.txt (line 5)) (1.11.0)
Requirement already satisfied, skipping upgrade: webencodings in /usr/local/lib/python3.5/dist-packages (from html5lib->-r requirements.txt (line 5)) (0.5.1)
"Building wheels for collected packages: predict
  Running setup.py bdist_wheel for predict: started"
"  Running setup.py bdist_wheel for predict: finished with status 'done'
  Stored in directory: /tmp/pip-ephem-wheel-cache-c06fry9j/wheels/35/24/16/37574d11bf9bde50616c67372a334f94fa8356bc7164af8ca3"
Successfully built predict
"Installing collected packages: predict
  Found existing installation: predict 1.0.0
    Uninstalling predict-1.0.0:
      Successfully uninstalled predict-1.0.0"
Successfully installed predict-1.0.0
You are using pip version 18.1, however version 20.3.4 is available.
You should consider upgrading via the 'pip install --upgrade pip' command.
[2021-02-12 16:18:03 +0000] [28] [ERROR] Error handling request /ping
"Traceback (most recent call last):
  File ""/usr/local/lib/python3.5/dist-packages/sagemaker_containers/_modules.py"", line 248, in import_module
    module = importlib.import_module(name)
  File ""/usr/lib/python3.5/importlib/__init__.py"", line 126, in import_module
    return _bootstrap._gcd_import(name[level:], package, level)
  File ""<frozen importlib._bootstrap>"", line 986, in _gcd_import
  File ""<frozen importlib._bootstrap>"", line 969, in _find_and_load
  File ""<frozen importlib._bootstrap>"", line 958, in _find_and_load_unlocked
  File ""<frozen importlib._bootstrap>"", line 673, in _load_unlocked
  File ""<frozen importlib._bootstrap_external>"", line 665, in exec_module
  File ""<frozen importlib._bootstrap>"", line 222, in _call_with_frames_removed
  File ""/usr/local/lib/python3.5/dist-packages/predict.py"", line 7, in <module>
    import pandas as pd
  File ""/usr/local/lib/python3.5/dist-packages/pandas/__init__.py"", line 42, in <module>
    from pandas.core.api import *
  File ""/usr/local/lib/python3.5/dist-packages/pandas/core/api.py"", line 7, in <module>
    from pandas.core.arrays.integer import (
  File ""/usr/local/lib/python3.5/dist-packages/pandas/core/arrays/__init__.py"", line 2, in <module>
    from .base import (ExtensionArray,    # noqa
  File ""/usr/local/lib/python3.5/dist-packages/pandas/core/arrays/base.py"", line 21, in <module>
    from pandas.core import ops"
"10.32.0.2 - - [12/Feb/2021:16:18:03 +0000] ""GET /ping HTTP/1.1"" 500 141 ""-"" ""AHC/2.0""
  File ""/usr/local/lib/python3.5/dist-packages/pandas/core/ops.py"", line 17, in <module>
    import pandas.compat as compat"
"AttributeError: module 'pandas' has no attribute 'compat'
"
"During handling of the above exception, another exception occurred:
"
"Traceback (most recent call last):
  File ""/usr/local/lib/python3.5/dist-packages/gunicorn/workers/base_async.py"", line 56, in handle
    self.handle_request(listener_name, req, client, addr)
  File ""/usr/local/lib/python3.5/dist-packages/gunicorn/workers/ggevent.py"", line 160, in handle_request
    addr)
  File ""/usr/local/lib/python3.5/dist-packages/gunicorn/workers/base_async.py"", line 107, in handle_request
    respiter = self.wsgi(environ, resp.start_response)
  File ""/usr/local/lib/python3.5/dist-packages/sagemaker_pytorch_container/serving.py"", line 103, in main
    user_module = modules.import_module(serving_env.module_dir, serving_env.module_name)
  File ""/usr/local/lib/python3.5/dist-packages/sagemaker_containers/_modules.py"", line 253, in import_module
    six.reraise(_errors.ImportModuleError, _errors.ImportModuleError(e), sys.exc_info()[2])
  File ""/usr/local/lib/python3.5/dist-packages/six.py"", line 692, in reraise
    raise value.with_traceback(tb)
  File ""/usr/local/lib/python3.5/dist-packages/sagemaker_containers/_modules.py"", line 248, in import_module
    module = importlib.import_module(name)
  File ""/usr/lib/python3.5/importlib/__init__.py"", line 126, in import_module
    return _bootstrap._gcd_import(name[level:], package, level)
  File ""<frozen importlib._bootstrap>"", line 986, in _gcd_import
  File ""<frozen importlib._bootstrap>"", line 969, in _find_and_load
  File ""<frozen importlib._bootstrap>"", line 958, in _find_and_load_unlocked
  File ""<frozen importlib._bootstrap>"", line 673, in _load_unlocked
  File ""<frozen importlib._bootstrap_external>"", line 665, in exec_module
  File ""<frozen importlib._bootstrap>"", line 222, in _call_with_frames_removed
  File ""/usr/local/lib/python3.5/dist-packages/predict.py"", line 7, in <module>
    import pandas as pd
  File ""/usr/local/lib/python3.5/dist-packages/pandas/__init__.py"", line 42, in <module>
    from pandas.core.api import *
  File ""/usr/local/lib/python3.5/dist-packages/pandas/core/api.py"", line 7, in <module>
    from pandas.core.arrays.integer import (
  File ""/usr/local/lib/python3.5/dist-packages/pandas/core/arrays/__init__.py"", line 2, in <module>
    from .base import (ExtensionArray,    # noqa
  File ""/usr/local/lib/python3.5/dist-packages/pandas/core/arrays/base.py"", line 21, in <module>
    from pandas.core import ops
  File ""/usr/local/lib/python3.5/dist-packages/pandas/core/ops.py"", line 17, in <module>
    import pandas.compat as compat"
sagemaker_containers._errors.ImportModuleError: module 'pandas' has no attribute 'compat'
Successfully installed beautifulsoup4-4.9.3 html5lib-1.1 nltk-3.5 pandas-0.24.2 predict-1.0.0 webencodings-0.5.1
You are using pip version 18.1, however version 20.3.4 is available.
You should consider upgrading via the 'pip install --upgrade pip' command.
Loading model.
model_info: {'hidden_dim': 200, 'vocab_size': 5000, 'embedding_dim': 32}
Done loading model.
"10.32.0.2 - - [12/Feb/2021:16:18:04 +0000] ""GET /ping HTTP/1.1"" 200 0 ""-"" ""AHC/2.0"""
Processing /opt/ml/code
Requirement already up-to-date: pandas in /usr/local/lib/python3.5/dist-packages (from -r requirements.txt (line 1)) (0.24.2)
Requirement already up-to-date: numpy in /usr/local/lib/python3.5/dist-packages (from -r requirements.txt (line 2)) (1.18.5)
Requirement already up-to-date: nltk in /usr/local/lib/python3.5/dist-packages (from -r requirements.txt (line 3)) (3.5)
Requirement already up-to-date: beautifulsoup4 in /usr/local/lib/python3.5/dist-packages (from -r requirements.txt (line 4)) (4.9.3)
Requirement already up-to-date: html5lib in /usr/local/lib/python3.5/dist-packages (from -r requirements.txt (line 5)) (1.1)
Requirement already satisfied, skipping upgrade: python-dateutil>=2.5.0 in /usr/local/lib/python3.5/dist-packages (from pandas->-r requirements.txt (line 1)) (2.7.5)
Requirement already satisfied, skipping upgrade: pytz>=2011k in /usr/local/lib/python3.5/dist-packages (from pandas->-r requirements.txt (line 1)) (2021.1)
Requirement already satisfied, skipping upgrade: tqdm in /usr/local/lib/python3.5/dist-packages (from nltk->-r requirements.txt (line 3)) (4.56.2)
Requirement already satisfied, skipping upgrade: joblib in /usr/local/lib/python3.5/dist-packages (from nltk->-r requirements.txt (line 3)) (0.14.1)
Requirement already satisfied, skipping upgrade: click in /usr/local/lib/python3.5/dist-packages (from nltk->-r requirements.txt (line 3)) (7.0)
Requirement already satisfied, skipping upgrade: regex in /usr/local/lib/python3.5/dist-packages (from nltk->-r requirements.txt (line 3)) (2020.11.13)
"Requirement already satisfied, skipping upgrade: soupsieve>1.2; python_version >= ""3.0"" in /usr/local/lib/python3.5/dist-packages (from beautifulsoup4->-r requirements.txt (line 4)) (2.1)"
Requirement already satisfied, skipping upgrade: six>=1.9 in /usr/local/lib/python3.5/dist-packages (from html5lib->-r requirements.txt (line 5)) (1.11.0)
Requirement already satisfied, skipping upgrade: webencodings in /usr/local/lib/python3.5/dist-packages (from html5lib->-r requirements.txt (line 5)) (0.5.1)
"Building wheels for collected packages: predict
  Running setup.py bdist_wheel for predict: started
  Running setup.py bdist_wheel for predict: finished with status 'done'
  Stored in directory: /tmp/pip-ephem-wheel-cache-kxo591f9/wheels/35/24/16/37574d11bf9bde50616c67372a334f94fa8356bc7164af8ca3"
Successfully built predict
"Installing collected packages: predict
  Found existing installation: predict 1.0.0
    Uninstalling predict-1.0.0:
      Successfully uninstalled predict-1.0.0"
Successfully installed predict-1.0.0
You are using pip version 18.1, however version 20.3.4 is available.
You should consider upgrading via the 'pip install --upgrade pip' command.
[2021-02-12 16:18:07 +0000] [27] [ERROR] Error handling request /ping
"Traceback (most recent call last):
  File ""/usr/local/lib/python3.5/dist-packages/sagemaker_containers/_modules.py"", line 248, in import_module
    module = importlib.import_module(name)
  File ""/usr/lib/python3.5/importlib/__init__.py"", line 126, in import_module
    return _bootstrap._gcd_import(name[level:], package, level)
  File ""<frozen importlib._bootstrap>"", line 986, in _gcd_import
  File ""<frozen importlib._bootstrap>"", line 969, in _find_and_load
  File ""<frozen importlib._bootstrap>"", line 958, in _find_and_load_unlocked
  File ""<frozen importlib._bootstrap>"", line 673, in _load_unlocked
  File ""<frozen importlib._bootstrap_external>"", line 665, in exec_module
  File ""<frozen importlib._bootstrap>"", line 222, in _call_with_frames_removed
  File ""/usr/local/lib/python3.5/dist-packages/predict.py"", line 7, in <module>
    import pandas as pd
  File ""/usr/local/lib/python3.5/dist-packages/pandas/__init__.py"", line 42, in <module>
    from pandas.core.api import *
  File ""/usr/local/lib/python3.5/dist-packages/pandas/core/api.py"", line 7, in <module>
    from pandas.core.arrays.integer import (
  File ""/usr/local/lib/python3.5/dist-packages/pandas/core/arrays/__init__.py"", line 2, in <module>
    from .base import (ExtensionArray,    # noqa
  File ""/usr/local/lib/python3.5/dist-packages/pandas/core/arrays/base.py"", line 21, in <module>
    from pandas.core import ops
  File ""/usr/local/lib/python3.5/dist-packages/pandas/core/ops.py"", line 17, in <module>
    import pandas.compat as compat"
"AttributeError: module 'pandas' has no attribute 'compat'
"
"During handling of the above exception, another exception occurred:
"
"Traceback (most recent call last):
  File ""/usr/local/lib/python3.5/dist-packages/gunicorn/workers/base_async.py"", line 56, in handle
    self.handle_request(listener_name, req, client, addr)
  File ""/usr/local/lib/python3.5/dist-packages/gunicorn/workers/ggevent.py"", line 160, in handle_request
    addr)
  File ""/usr/local/lib/python3.5/dist-packages/gunicorn/workers/base_async.py"", line 107, in handle_request
    respiter = self.wsgi(environ, resp.start_response)"
"10.32.0.2 - - [12/Feb/2021:16:18:07 +0000] ""GET /ping HTTP/1.1"" 500 141 ""-"" ""AHC/2.0""
  File ""/usr/local/lib/python3.5/dist-packages/sagemaker_pytorch_container/serving.py"", line 103, in main
    user_module = modules.import_module(serving_env.module_dir, serving_env.module_name)
  File ""/usr/local/lib/python3.5/dist-packages/sagemaker_containers/_modules.py"", line 253, in import_module
    six.reraise(_errors.ImportModuleError, _errors.ImportModuleError(e), sys.exc_info()[2])
  File ""/usr/local/lib/python3.5/dist-packages/six.py"", line 692, in reraise
    raise value.with_traceback(tb)
  File ""/usr/local/lib/python3.5/dist-packages/sagemaker_containers/_modules.py"", line 248, in import_module
    module = importlib.import_module(name)
  File ""/usr/lib/python3.5/importlib/__init__.py"", line 126, in import_module
    return _bootstrap._gcd_import(name[level:], package, level)
  File ""<frozen importlib._bootstrap>"", line 986, in _gcd_import
  File ""<frozen importlib._bootstrap>"", line 969, in _find_and_load
  File ""<frozen importlib._bootstrap>"", line 958, in _find_and_load_unlocked
  File ""<frozen importlib._bootstrap>"", line 673, in _load_unlocked
  File ""<frozen importlib._bootstrap_external>"", line 665, in exec_module
  File ""<frozen importlib._bootstrap>"", line 222, in _call_with_frames_removed
  File ""/usr/local/lib/python3.5/dist-packages/predict.py"", line 7, in <module>
    import pandas as pd
  File ""/usr/local/lib/python3.5/dist-packages/pandas/__init__.py"", line 42, in <module>
    from pandas.core.api import *
  File ""/usr/local/lib/python3.5/dist-packages/pandas/core/api.py"", line 7, in <module>
    from pandas.core.arrays.integer import (
  File ""/usr/local/lib/python3.5/dist-packages/pandas/core/arrays/__init__.py"", line 2, in <module>
    from .base import (ExtensionArray,    # noqa
  File ""/usr/local/lib/python3.5/dist-packages/pandas/core/arrays/base.py"", line 21, in <module>
    from pandas.core import ops
  File ""/usr/local/lib/python3.5/dist-packages/pandas/core/ops.py"", line 17, in <module>
    import pandas.compat as compat"
sagemaker_containers._errors.ImportModuleError: module 'pandas' has no attribute 'compat'
Processing /opt/ml/code
Requirement already up-to-date: pandas in /usr/local/lib/python3.5/dist-packages (from -r requirements.txt (line 1)) (0.24.2)
Requirement already up-to-date: numpy in /usr/local/lib/python3.5/dist-packages (from -r requirements.txt (line 2)) (1.18.5)
Requirement already up-to-date: nltk in /usr/local/lib/python3.5/dist-packages (from -r requirements.txt (line 3)) (3.5)
Requirement already up-to-date: beautifulsoup4 in /usr/local/lib/python3.5/dist-packages (from -r requirements.txt (line 4)) (4.9.3)
Requirement already up-to-date: html5lib in /usr/local/lib/python3.5/dist-packages (from -r requirements.txt (line 5)) (1.1)
Requirement already satisfied, skipping upgrade: python-dateutil>=2.5.0 in /usr/local/lib/python3.5/dist-packages (from pandas->-r requirements.txt (line 1)) (2.7.5)
Requirement already satisfied, skipping upgrade: pytz>=2011k in /usr/local/lib/python3.5/dist-packages (from pandas->-r requirements.txt (line 1)) (2021.1)
Requirement already satisfied, skipping upgrade: click in /usr/local/lib/python3.5/dist-packages (from nltk->-r requirements.txt (line 3)) (7.0)
Requirement already satisfied, skipping upgrade: joblib in /usr/local/lib/python3.5/dist-packages (from nltk->-r requirements.txt (line 3)) (0.14.1)
Requirement already satisfied, skipping upgrade: tqdm in /usr/local/lib/python3.5/dist-packages (from nltk->-r requirements.txt (line 3)) (4.56.2)
Requirement already satisfied, skipping upgrade: regex in /usr/local/lib/python3.5/dist-packages (from nltk->-r requirements.txt (line 3)) (2020.11.13)
"Requirement already satisfied, skipping upgrade: soupsieve>1.2; python_version >= ""3.0"" in /usr/local/lib/python3.5/dist-packages (from beautifulsoup4->-r requirements.txt (line 4)) (2.1)"
Requirement already satisfied, skipping upgrade: six>=1.9 in /usr/local/lib/python3.5/dist-packages (from html5lib->-r requirements.txt (line 5)) (1.11.0)
Requirement already satisfied, skipping upgrade: webencodings in /usr/local/lib/python3.5/dist-packages (from html5lib->-r requirements.txt (line 5)) (0.5.1)
"Building wheels for collected packages: predict
  Running setup.py bdist_wheel for predict: started
  Running setup.py bdist_wheel for predict: finished with status 'done'
  Stored in directory: /tmp/pip-ephem-wheel-cache-e3t7zk_y/wheels/35/24/16/37574d11bf9bde50616c67372a334f94fa8356bc7164af8ca3"
Successfully built predict
"Installing collected packages: predict
  Found existing installation: predict 1.0.0
    Uninstalling predict-1.0.0:
      Successfully uninstalled predict-1.0.0"
Successfully installed predict-1.0.0
You are using pip version 18.1, however version 20.3.4 is available.
You should consider upgrading via the 'pip install --upgrade pip' command.
[2021-02-12 16:18:12 +0000] [28] [ERROR] Error handling request /ping
"Traceback (most recent call last):
  File ""/usr/local/lib/python3.5/dist-packages/sagemaker_containers/_modules.py"", line 248, in import_module
    module = importlib.import_module(name)
  File ""/usr/lib/python3.5/importlib/__init__.py"", line 126, in import_module
    return _bootstrap._gcd_import(name[level:], package, level)
  File ""<frozen importlib._bootstrap>"", line 986, in _gcd_import
  File ""<frozen importlib._bootstrap>"", line 969, in _find_and_load
  File ""<frozen importlib._bootstrap>"", line 958, in _find_and_load_unlocked
  File ""<frozen importlib._bootstrap>"", line 673, in _load_unlocked
  File ""<frozen importlib._bootstrap_external>"", line 665, in exec_module
  File ""<frozen importlib._bootstrap>"", line 222, in _call_with_frames_removed
  File ""/usr/local/lib/python3.5/dist-packages/predict.py"", line 7, in <module>
    import pandas as pd
  File ""/usr/local/lib/python3.5/dist-packages/pandas/__init__.py"", line 42, in <module>
    from pandas.core.api import *
  File ""/usr/local/lib/python3.5/dist-packages/pandas/core/api.py"", line 7, in <module>
    from pandas.core.arrays.integer import (
  File ""/usr/local/lib/python3.5/dist-packages/pandas/core/arrays/__init__.py"", line 2, in <module>
    from .base import (ExtensionArray,    # noqa
  File ""/usr/local/lib/python3.5/dist-packages/pandas/core/arrays/base.py"", line 21, in <module>
    from pandas.core import ops
  File ""/usr/local/lib/python3.5/dist-packages/pandas/core/ops.py"", line 17, in <module>
    import pandas.compat as compat"
"AttributeError: module 'pandas' has no attribute 'compat'
"
"During handling of the above exception, another exception occurred:
"
"Traceback (most recent call last):
  File ""/usr/local/lib/python3.5/dist-packages/gunicorn/workers/base_async.py"", line 56, in handle
    self.handle_request(listener_name, req, client, addr)
  File ""/usr/local/lib/python3.5/dist-packages/gunicorn/workers/ggevent.py"", line 160, in handle_request
    addr)
  File ""/usr/local/lib/python3.5/dist-packages/gunicorn/workers/base_async.py"", line 107, in handle_request
    respiter = self.wsgi(environ, resp.start_response)
  File ""/usr/local/lib/python3.5/dist-packages/sagemaker_pytorch_container/serving.py"", line 103, in main
    user_module = modules.import_module(serving_env.module_dir, serving_env.module_name)
  File ""/usr/local/lib/python3.5/dist-packages/sagemaker_containers/_modules.py"", line 253, in import_module
    six.reraise(_errors.ImportModuleError, _errors.ImportModuleError(e), sys.exc_info()[2])
  File ""/usr/local/lib/python3.5/dist-packages/six.py"", line 692, in reraise
    raise value.with_traceback(tb)
  File ""/usr/local/lib/python3.5/dist-packages/sagemaker_containers/_modules.py"", line 248, in import_module
    module = importlib.import_module(name)
  File ""/usr/lib/python3.5/importlib/__init__.py"", line 126, in import_module
    return _bootstrap._gcd_import(name[level:], package, level)
  File ""<frozen importlib._bootstrap>"", line 986, in _gcd_import
  File ""<frozen importlib._bootstrap>"", line 969, in _find_and_load
  File ""<frozen importlib._bootstrap>"", line 958, in _find_and_load_unlocked
  File ""<frozen importlib._bootstrap>"", line 673, in _load_unlocked
  File ""<frozen importlib._bootstrap_external>"", line 665, in exec_module
  File ""<frozen importlib._bootstrap>"", line 222, in _call_with_frames_removed
  File ""/usr/local/lib/python3.5/dist-packages/predict.py"", line 7, in <module>
    import pandas as pd
  File ""/usr/local/lib/python3.5/dist-packages/pandas/__init__.py"", line 42, in <module>
    from pandas.core.api import *
  File ""/usr/local/lib/python3.5/dist-packages/pandas/core/api.py"", line 7, in <module>
    from pandas.core.arrays.integer import (
  File ""/usr/local/lib/python3.5/dist-packages/pandas/core/arrays/__init__.py"", line 2, in <module>
    from .base import (ExtensionArray,    # noqa
  File ""/usr/local/lib/python3.5/dist-packages/pandas/core/arrays/base.py"", line 21, in <module>
    from pandas.core import ops
  File ""/usr/local/lib/python3.5/dist-packages/pandas/core/ops.py"", line 17, in <module>
    import pandas.compat as compat"
sagemaker_containers._errors.ImportModuleError: module 'pandas' has no attribute 'compat'
"10.32.0.2 - - [12/Feb/2021:16:18:12 +0000] ""GET /ping HTTP/1.1"" 500 141 ""-"" ""AHC/2.0"""
"10.32.0.2 - - [12/Feb/2021:16:18:15 +0000] ""GET /ping HTTP/1.1"" 200 0 ""-"" ""AHC/2.0"""
"10.32.0.2 - - [12/Feb/2021:16:18:20 +0000] ""GET /ping HTTP/1.1"" 200 0 ""-"" ""AHC/2.0"""
"10.32.0.2 - - [12/Feb/2021:16:18:25 +0000] ""GET /ping HTTP/1.1"" 200 0 ""-"" ""AHC/2.0"""
Processing /opt/ml/code
Requirement already up-to-date: pandas in /usr/local/lib/python3.5/dist-packages (from -r requirements.txt (line 1)) (0.24.2)
Requirement already up-to-date: numpy in /usr/local/lib/python3.5/dist-packages (from -r requirements.txt (line 2)) (1.18.5)
Requirement already up-to-date: nltk in /usr/local/lib/python3.5/dist-packages (from -r requirements.txt (line 3)) (3.5)
Requirement already up-to-date: beautifulsoup4 in /usr/local/lib/python3.5/dist-packages (from -r requirements.txt (line 4)) (4.9.3)
Requirement already up-to-date: html5lib in /usr/local/lib/python3.5/dist-packages (from -r requirements.txt (line 5)) (1.1)
Requirement already satisfied, skipping upgrade: pytz>=2011k in /usr/local/lib/python3.5/dist-packages (from pandas->-r requirements.txt (line 1)) (2021.1)
Requirement already satisfied, skipping upgrade: python-dateutil>=2.5.0 in /usr/local/lib/python3.5/dist-packages (from pandas->-r requirements.txt (line 1)) (2.7.5)
Requirement already satisfied, skipping upgrade: regex in /usr/local/lib/python3.5/dist-packages (from nltk->-r requirements.txt (line 3)) (2020.11.13)
Requirement already satisfied, skipping upgrade: joblib in /usr/local/lib/python3.5/dist-packages (from nltk->-r requirements.txt (line 3)) (0.14.1)
Requirement already satisfied, skipping upgrade: tqdm in /usr/local/lib/python3.5/dist-packages (from nltk->-r requirements.txt (line 3)) (4.56.2)
Requirement already satisfied, skipping upgrade: click in /usr/local/lib/python3.5/dist-packages (from nltk->-r requirements.txt (line 3)) (7.0)
"Requirement already satisfied, skipping upgrade: soupsieve>1.2; python_version >= ""3.0"" in /usr/local/lib/python3.5/dist-packages (from beautifulsoup4->-r requirements.txt (line 4)) (2.1)"
Requirement already satisfied, skipping upgrade: six>=1.9 in /usr/local/lib/python3.5/dist-packages (from html5lib->-r requirements.txt (line 5)) (1.11.0)
Requirement already satisfied, skipping upgrade: webencodings in /usr/local/lib/python3.5/dist-packages (from html5lib->-r requirements.txt (line 5)) (0.5.1)
"Building wheels for collected packages: predict
  Running setup.py bdist_wheel for predict: started
  Running setup.py bdist_wheel for predict: finished with status 'done'
  Stored in directory: /tmp/pip-ephem-wheel-cache-ae3cfhy6/wheels/35/24/16/37574d11bf9bde50616c67372a334f94fa8356bc7164af8ca3"
Successfully built predict
"Installing collected packages: predict
  Found existing installation: predict 1.0.0
    Uninstalling predict-1.0.0:
      Successfully uninstalled predict-1.0.0"
Successfully installed predict-1.0.0
You are using pip version 18.1, however version 20.3.4 is available.
You should consider upgrading via the 'pip install --upgrade pip' command.
[2021-02-12 16:18:32 +0000] [27] [ERROR] Error handling request /ping
"Traceback (most recent call last):
  File ""/usr/local/lib/python3.5/dist-packages/sagemaker_containers/_modules.py"", line 248, in import_module
    module = importlib.import_module(name)
  File ""/usr/lib/python3.5/importlib/__init__.py"", line 126, in import_module
    return _bootstrap._gcd_import(name[level:], package, level)
  File ""<frozen importlib._bootstrap>"", line 986, in _gcd_import
  File ""<frozen importlib._bootstrap>"", line 969, in _find_and_load
  File ""<frozen importlib._bootstrap>"", line 958, in _find_and_load_unlocked
  File ""<frozen importlib._bootstrap>"", line 673, in _load_unlocked
  File ""<frozen importlib._bootstrap_external>"", line 665, in exec_module
  File ""<frozen importlib._bootstrap>"", line 222, in _call_with_frames_removed
  File ""/usr/local/lib/python3.5/dist-packages/predict.py"", line 7, in <module>
    import pandas as pd
  File ""/usr/local/lib/python3.5/dist-packages/pandas/__init__.py"", line 42, in <module>
    from pandas.core.api import *
  File ""/usr/local/lib/python3.5/dist-packages/pandas/core/api.py"", line 7, in <module>
    from pandas.core.arrays.integer import (
  File ""/usr/local/lib/python3.5/dist-packages/pandas/core/arrays/__init__.py"", line 2, in <module>
    from .base import (ExtensionArray,    # noqa
  File ""/usr/local/lib/python3.5/dist-packages/pandas/core/arrays/base.py"", line 21, in <module>
    from pandas.core import ops
  File ""/usr/local/lib/python3.5/dist-packages/pandas/core/ops.py"", line 17, in <module>
    import pandas.compat as compat"
"AttributeError: module 'pandas' has no attribute 'compat'
"
"During handling of the above exception, another exception occurred:
"
"Traceback (most recent call last):
  File ""/usr/local/lib/python3.5/dist-packages/gunicorn/workers/base_async.py"", line 56, in handle
    self.handle_request(listener_name, req, client, addr)
  File ""/usr/local/lib/python3.5/dist-packages/gunicorn/workers/ggevent.py"", line 160, in handle_request
    addr)
  File ""/usr/local/lib/python3.5/dist-packages/gunicorn/workers/base_async.py"", line 107, in handle_request
    respiter = self.wsgi(environ, resp.start_response)
  File ""/usr/local/lib/python3.5/dist-packages/sagemaker_pytorch_container/serving.py"", line 103, in main
    user_module = modules.import_module(serving_env.module_dir, serving_env.module_name)
  File ""/usr/local/lib/python3.5/dist-packages/sagemaker_containers/_modules.py"", line 253, in import_module
    six.reraise(_errors.ImportModuleError, _errors.ImportModuleError(e), sys.exc_info()[2])
  File ""/usr/local/lib/python3.5/dist-packages/six.py"", line 692, in reraise
    raise value.with_traceback(tb)
  File ""/usr/local/lib/python3.5/dist-packages/sagemaker_containers/_modules.py"", line 248, in import_module
    module = importlib.import_module(name)
  File ""/usr/lib/python3.5/importlib/__init__.py"", line 126, in import_module
    return _bootstrap._gcd_import(name[level:], package, level)
  File ""<frozen importlib._bootstrap>"", line 986, in _gcd_import
  File ""<frozen importlib._bootstrap>"", line 969, in _find_and_load
  File ""<frozen importlib._bootstrap>"", line 958, in _find_and_load_unlocked
  File ""<frozen importlib._bootstrap>"", line 673, in _load_unlocked
  File ""<frozen importlib._bootstrap_external>"", line 665, in exec_module
  File ""<frozen importlib._bootstrap>"", line 222, in _call_with_frames_removed
  File ""/usr/local/lib/python3.5/dist-packages/predict.py"", line 7, in <module>
    import pandas as pd
  File ""/usr/local/lib/python3.5/dist-packages/pandas/__init__.py"", line 42, in <module>
    from pandas.core.api import *
  File ""/usr/local/lib/python3.5/dist-packages/pandas/core/api.py"", line 7, in <module>
    from pandas.core.arrays.integer import (
  File ""/usr/local/lib/python3.5/dist-packages/pandas/core/arrays/__init__.py"", line 2, in <module>
    from .base import (ExtensionArray,    # noqa
  File ""/usr/local/lib/python3.5/dist-packages/pandas/core/arrays/base.py"", line 21, in <module>
    from pandas.core import ops
  File ""/usr/local/lib/python3.5/dist-packages/pandas/core/ops.py"", line 17, in <module>
    import pandas.compat as compat"
"10.32.0.2 - - [12/Feb/2021:16:18:32 +0000] ""GET /ping HTTP/1.1"" 500 141 ""-"" ""AHC/2.0"""
sagemaker_containers._errors.ImportModuleError: module 'pandas' has no attribute 'compat'
Processing /opt/ml/code
Requirement already up-to-date: pandas in /usr/local/lib/python3.5/dist-packages (from -r requirements.txt (line 1)) (0.24.2)
Requirement already up-to-date: numpy in /usr/local/lib/python3.5/dist-packages (from -r requirements.txt (line 2)) (1.18.5)
Requirement already up-to-date: nltk in /usr/local/lib/python3.5/dist-packages (from -r requirements.txt (line 3)) (3.5)
Requirement already up-to-date: beautifulsoup4 in /usr/local/lib/python3.5/dist-packages (from -r requirements.txt (line 4)) (4.9.3)
Requirement already up-to-date: html5lib in /usr/local/lib/python3.5/dist-packages (from -r requirements.txt (line 5)) (1.1)
Requirement already satisfied, skipping upgrade: pytz>=2011k in /usr/local/lib/python3.5/dist-packages (from pandas->-r requirements.txt (line 1)) (2021.1)
Requirement already satisfied, skipping upgrade: python-dateutil>=2.5.0 in /usr/local/lib/python3.5/dist-packages (from pandas->-r requirements.txt (line 1)) (2.7.5)
Requirement already satisfied, skipping upgrade: regex in /usr/local/lib/python3.5/dist-packages (from nltk->-r requirements.txt (line 3)) (2020.11.13)
Requirement already satisfied, skipping upgrade: click in /usr/local/lib/python3.5/dist-packages (from nltk->-r requirements.txt (line 3)) (7.0)
Requirement already satisfied, skipping upgrade: joblib in /usr/local/lib/python3.5/dist-packages (from nltk->-r requirements.txt (line 3)) (0.14.1)
Requirement already satisfied, skipping upgrade: tqdm in /usr/local/lib/python3.5/dist-packages (from nltk->-r requirements.txt (line 3)) (4.56.2)
"Requirement already satisfied, skipping upgrade: soupsieve>1.2; python_version >= ""3.0"" in /usr/local/lib/python3.5/dist-packages (from beautifulsoup4->-r requirements.txt (line 4)) (2.1)"
Requirement already satisfied, skipping upgrade: webencodings in /usr/local/lib/python3.5/dist-packages (from html5lib->-r requirements.txt (line 5)) (0.5.1)
Requirement already satisfied, skipping upgrade: six>=1.9 in /usr/local/lib/python3.5/dist-packages (from html5lib->-r requirements.txt (line 5)) (1.11.0)
"Building wheels for collected packages: predict
  Running setup.py bdist_wheel for predict: started
  Running setup.py bdist_wheel for predict: finished with status 'done'
  Stored in directory: /tmp/pip-ephem-wheel-cache-jgj191dn/wheels/35/24/16/37574d11bf9bde50616c67372a334f94fa8356bc7164af8ca3"
Successfully built predict
"Installing collected packages: predict
  Found existing installation: predict 1.0.0
    Uninstalling predict-1.0.0:
      Successfully uninstalled predict-1.0.0"
Successfully installed predict-1.0.0
You are using pip version 18.1, however version 20.3.4 is available.
You should consider upgrading via the 'pip install --upgrade pip' command.
[2021-02-12 16:18:37 +0000] [28] [ERROR] Error handling request /ping
"Traceback (most recent call last):
  File ""/usr/local/lib/python3.5/dist-packages/sagemaker_containers/_modules.py"", line 248, in import_module
    module = importlib.import_module(name)
  File ""/usr/lib/python3.5/importlib/__init__.py"", line 126, in import_module
    return _bootstrap._gcd_import(name[level:], package, level)
  File ""<frozen importlib._bootstrap>"", line 986, in _gcd_import
  File ""<frozen importlib._bootstrap>"", line 969, in _find_and_load
  File ""<frozen importlib._bootstrap>"", line 958, in _find_and_load_unlocked
  File ""<frozen importlib._bootstrap>"", line 673, in _load_unlocked
  File ""<frozen importlib._bootstrap_external>"", line 665, in exec_module
  File ""<frozen importlib._bootstrap>"", line 222, in _call_with_frames_removed
  File ""/usr/local/lib/python3.5/dist-packages/predict.py"", line 7, in <module>
    import pandas as pd
  File ""/usr/local/lib/python3.5/dist-packages/pandas/__init__.py"", line 42, in <module>
    from pandas.core.api import *
  File ""/usr/local/lib/python3.5/dist-packages/pandas/core/api.py"", line 7, in <module>
    from pandas.core.arrays.integer import (
  File ""/usr/local/lib/python3.5/dist-packages/pandas/core/arrays/__init__.py"", line 2, in <module>
    from .base import (ExtensionArray,    # noqa
  File ""/usr/local/lib/python3.5/dist-packages/pandas/core/arrays/base.py"", line 21, in <module>
    from pandas.core import ops
  File ""/usr/local/lib/python3.5/dist-packages/pandas/core/ops.py"", line 17, in <module>
    import pandas.compat as compat"
"AttributeError: module 'pandas' has no attribute 'compat'
"
"During handling of the above exception, another exception occurred:
"
"Traceback (most recent call last):
  File ""/usr/local/lib/python3.5/dist-packages/gunicorn/workers/base_async.py"", line 56, in handle
    self.handle_request(listener_name, req, client, addr)
  File ""/usr/local/lib/python3.5/dist-packages/gunicorn/workers/ggevent.py"", line 160, in handle_request
    addr)
  File ""/usr/local/lib/python3.5/dist-packages/gunicorn/workers/base_async.py"", line 107, in handle_request
    respiter = self.wsgi(environ, resp.start_response)
  File ""/usr/local/lib/python3.5/dist-packages/sagemaker_pytorch_container/serving.py"", line 103, in main
    user_module = modules.import_module(serving_env.module_dir, serving_env.module_name)
  File ""/usr/local/lib/python3.5/dist-packages/sagemaker_containers/_modules.py"", line 253, in import_module
    six.reraise(_errors.ImportModuleError, _errors.ImportModuleError(e), sys.exc_info()[2])
  File ""/usr/local/lib/python3.5/dist-packages/six.py"", line 692, in reraise
    raise value.with_traceback(tb)
  File ""/usr/local/lib/python3.5/dist-packages/sagemaker_containers/_modules.py"", line 248, in import_module
    module = importlib.import_module(name)
  File ""/usr/lib/python3.5/importlib/__init__.py"", line 126, in import_module
    return _bootstrap._gcd_import(name[level:], package, level)
  File ""<frozen importlib._bootstrap>"", line 986, in _gcd_import
  File ""<frozen importlib._bootstrap>"", line 969, in _find_and_load
  File ""<frozen importlib._bootstrap>"", line 958, in _find_and_load_unlocked
  File ""<frozen importlib._bootstrap>"", line 673, in _load_unlocked
  File ""<frozen importlib._bootstrap_external>"", line 665, in exec_module
  File ""<frozen importlib._bootstrap>"", line 222, in _call_with_frames_removed
  File ""/usr/local/lib/python3.5/dist-packages/predict.py"", line 7, in <module>
    import pandas as pd
  File ""/usr/local/lib/python3.5/dist-packages/pandas/__init__.py"", line 42, in <module>
    from pandas.core.api import *
  File ""/usr/local/lib/python3.5/dist-packages/pandas/core/api.py"", line 7, in <module>
    from pandas.core.arrays.integer import (
  File ""/usr/local/lib/python3.5/dist-packages/pandas/core/arrays/__init__.py"", line 2, in <module>
    from .base import (ExtensionArray,    # noqa
  File ""/usr/local/lib/python3.5/dist-packages/pandas/core/arrays/base.py"", line 21, in <module>
    from pandas.core import ops
  File ""/usr/local/lib/python3.5/dist-packages/pandas/core/ops.py"", line 17, in <module>
    import pandas.compat as compat"
sagemaker_containers._errors.ImportModuleError: module 'pandas' has no attribute 'compat'
"10.32.0.2 - - [12/Feb/2021:16:18:37 +0000] ""GET /ping HTTP/1.1"" 500 141 ""-"" ""AHC/2.0"""
"10.32.0.2 - - [12/Feb/2021:16:18:40 +0000] ""GET /ping HTTP/1.1"" 200 0 ""-"" ""AHC/2.0"""
Processing /opt/ml/code
Requirement already up-to-date: pandas in /usr/local/lib/python3.5/dist-packages (from -r requirements.txt (line 1)) (0.24.2)
Requirement already up-to-date: numpy in /usr/local/lib/python3.5/dist-packages (from -r requirements.txt (line 2)) (1.18.5)
Requirement already up-to-date: nltk in /usr/local/lib/python3.5/dist-packages (from -r requirements.txt (line 3)) (3.5)
Requirement already up-to-date: beautifulsoup4 in /usr/local/lib/python3.5/dist-packages (from -r requirements.txt (line 4)) (4.9.3)
Requirement already up-to-date: html5lib in /usr/local/lib/python3.5/dist-packages (from -r requirements.txt (line 5)) (1.1)
Requirement already satisfied, skipping upgrade: python-dateutil>=2.5.0 in /usr/local/lib/python3.5/dist-packages (from pandas->-r requirements.txt (line 1)) (2.7.5)
Requirement already satisfied, skipping upgrade: pytz>=2011k in /usr/local/lib/python3.5/dist-packages (from pandas->-r requirements.txt (line 1)) (2021.1)
Requirement already satisfied, skipping upgrade: click in /usr/local/lib/python3.5/dist-packages (from nltk->-r requirements.txt (line 3)) (7.0)
Requirement already satisfied, skipping upgrade: tqdm in /usr/local/lib/python3.5/dist-packages (from nltk->-r requirements.txt (line 3)) (4.56.2)
Requirement already satisfied, skipping upgrade: regex in /usr/local/lib/python3.5/dist-packages (from nltk->-r requirements.txt (line 3)) (2020.11.13)
Requirement already satisfied, skipping upgrade: joblib in /usr/local/lib/python3.5/dist-packages (from nltk->-r requirements.txt (line 3)) (0.14.1)
"Requirement already satisfied, skipping upgrade: soupsieve>1.2; python_version >= ""3.0"" in /usr/local/lib/python3.5/dist-packages (from beautifulsoup4->-r requirements.txt (line 4)) (2.1)"
Requirement already satisfied, skipping upgrade: six>=1.9 in /usr/local/lib/python3.5/dist-packages (from html5lib->-r requirements.txt (line 5)) (1.11.0)
Requirement already satisfied, skipping upgrade: webencodings in /usr/local/lib/python3.5/dist-packages (from html5lib->-r requirements.txt (line 5)) (0.5.1)
"Building wheels for collected packages: predict
  Running setup.py bdist_wheel for predict: started
  Running setup.py bdist_wheel for predict: finished with status 'done'
  Stored in directory: /tmp/pip-ephem-wheel-cache-s2lw7mn4/wheels/35/24/16/37574d11bf9bde50616c67372a334f94fa8356bc7164af8ca3"
Successfully built predict
"Installing collected packages: predict
  Found existing installation: predict 1.0.0
    Uninstalling predict-1.0.0:
      Successfully uninstalled predict-1.0.0"
Successfully installed predict-1.0.0
You are using pip version 18.1, however version 20.3.4 is available.
You should consider upgrading via the 'pip install --upgrade pip' command.
[2021-02-12 16:18:47 +0000] [27] [ERROR] Error handling request /ping
"Traceback (most recent call last):
  File ""/usr/local/lib/python3.5/dist-packages/sagemaker_containers/_modules.py"", line 248, in import_module
    module = importlib.import_module(name)
  File ""/usr/lib/python3.5/importlib/__init__.py"", line 126, in import_module
    return _bootstrap._gcd_import(name[level:], package, level)
  File ""<frozen importlib._bootstrap>"", line 986, in _gcd_import
  File ""<frozen importlib._bootstrap>"", line 969, in _find_and_load
  File ""<frozen importlib._bootstrap>"", line 958, in _find_and_load_unlocked
  File ""<frozen importlib._bootstrap>"", line 673, in _load_unlocked
  File ""<frozen importlib._bootstrap_external>"", line 665, in exec_module
  File ""<frozen importlib._bootstrap>"", line 222, in _call_with_frames_removed
  File ""/usr/local/lib/python3.5/dist-packages/predict.py"", line 7, in <module>
    import pandas as pd
  File ""/usr/local/lib/python3.5/dist-packages/pandas/__init__.py"", line 42, in <module>
    from pandas.core.api import *
  File ""/usr/local/lib/python3.5/dist-packages/pandas/core/api.py"", line 7, in <module>
    from pandas.core.arrays.integer import (
  File ""/usr/local/lib/python3.5/dist-packages/pandas/core/arrays/__init__.py"", line 2, in <module>
    from .base import (ExtensionArray,    # noqa
  File ""/usr/local/lib/python3.5/dist-packages/pandas/core/arrays/base.py"", line 21, in <module>
    from pandas.core import ops
  File ""/usr/local/lib/python3.5/dist-packages/pandas/core/ops.py"", line 17, in <module>
    import pandas.compat as compat"
"AttributeError: module 'pandas' has no attribute 'compat'
"
"During handling of the above exception, another exception occurred:
"
"Traceback (most recent call last):
  File ""/usr/local/lib/python3.5/dist-packages/gunicorn/workers/base_async.py"", line 56, in handle
    self.handle_request(listener_name, req, client, addr)
  File ""/usr/local/lib/python3.5/dist-packages/gunicorn/workers/ggevent.py"", line 160, in handle_request
    addr)
  File ""/usr/local/lib/python3.5/dist-packages/gunicorn/workers/base_async.py"", line 107, in handle_request
    respiter = self.wsgi(environ, resp.start_response)
  File ""/usr/local/lib/python3.5/dist-packages/sagemaker_pytorch_container/serving.py"", line 103, in main
    user_module = modules.import_module(serving_env.module_dir, serving_env.module_name)
  File ""/usr/local/lib/python3.5/dist-packages/sagemaker_containers/_modules.py"", line 253, in import_module
    six.reraise(_errors.ImportModuleError, _errors.ImportModuleError(e), sys.exc_info()[2])
  File ""/usr/local/lib/python3.5/dist-packages/six.py"", line 692, in reraise
    raise value.with_traceback(tb)
  File ""/usr/local/lib/python3.5/dist-packages/sagemaker_containers/_modules.py"", line 248, in import_module
    module = importlib.import_module(name)
  File ""/usr/lib/python3.5/importlib/__init__.py"", line 126, in import_module
    return _bootstrap._gcd_import(name[level:], package, level)"
"10.32.0.2 - - [12/Feb/2021:16:18:47 +0000] ""GET /ping HTTP/1.1"" 500 141 ""-"" ""AHC/2.0""
  File ""<frozen importlib._bootstrap>"", line 986, in _gcd_import
  File ""<frozen importlib._bootstrap>"", line 969, in _find_and_load
  File ""<frozen importlib._bootstrap>"", line 958, in _find_and_load_unlocked
  File ""<frozen importlib._bootstrap>"", line 673, in _load_unlocked
  File ""<frozen importlib._bootstrap_external>"", line 665, in exec_module
  File ""<frozen importlib._bootstrap>"", line 222, in _call_with_frames_removed
  File ""/usr/local/lib/python3.5/dist-packages/predict.py"", line 7, in <module>
    import pandas as pd
  File ""/usr/local/lib/python3.5/dist-packages/pandas/__init__.py"", line 42, in <module>
    from pandas.core.api import *
  File ""/usr/local/lib/python3.5/dist-packages/pandas/core/api.py"", line 7, in <module>
    from pandas.core.arrays.integer import (
  File ""/usr/local/lib/python3.5/dist-packages/pandas/core/arrays/__init__.py"", line 2, in <module>
    from .base import (ExtensionArray,    # noqa
  File ""/usr/local/lib/python3.5/dist-packages/pandas/core/arrays/base.py"", line 21, in <module>
    from pandas.core import ops
  File ""/usr/local/lib/python3.5/dist-packages/pandas/core/ops.py"", line 17, in <module>
    import pandas.compat as compat"
sagemaker_containers._errors.ImportModuleError: module 'pandas' has no attribute 'compat'
"10.32.0.2 - - [12/Feb/2021:16:18:50 +0000] ""GET /ping HTTP/1.1"" 200 0 ""-"" ""AHC/2.0"""
Processing /opt/ml/code
Requirement already up-to-date: pandas in /usr/local/lib/python3.5/dist-packages (from -r requirements.txt (line 1)) (0.24.2)
Requirement already up-to-date: numpy in /usr/local/lib/python3.5/dist-packages (from -r requirements.txt (line 2)) (1.18.5)
Requirement already up-to-date: nltk in /usr/local/lib/python3.5/dist-packages (from -r requirements.txt (line 3)) (3.5)
Requirement already up-to-date: beautifulsoup4 in /usr/local/lib/python3.5/dist-packages (from -r requirements.txt (line 4)) (4.9.3)
Requirement already up-to-date: html5lib in /usr/local/lib/python3.5/dist-packages (from -r requirements.txt (line 5)) (1.1)
Requirement already satisfied, skipping upgrade: pytz>=2011k in /usr/local/lib/python3.5/dist-packages (from pandas->-r requirements.txt (line 1)) (2021.1)
Requirement already satisfied, skipping upgrade: python-dateutil>=2.5.0 in /usr/local/lib/python3.5/dist-packages (from pandas->-r requirements.txt (line 1)) (2.7.5)
Requirement already satisfied, skipping upgrade: regex in /usr/local/lib/python3.5/dist-packages (from nltk->-r requirements.txt (line 3)) (2020.11.13)
Requirement already satisfied, skipping upgrade: tqdm in /usr/local/lib/python3.5/dist-packages (from nltk->-r requirements.txt (line 3)) (4.56.2)
Requirement already satisfied, skipping upgrade: click in /usr/local/lib/python3.5/dist-packages (from nltk->-r requirements.txt (line 3)) (7.0)
Requirement already satisfied, skipping upgrade: joblib in /usr/local/lib/python3.5/dist-packages (from nltk->-r requirements.txt (line 3)) (0.14.1)
"Requirement already satisfied, skipping upgrade: soupsieve>1.2; python_version >= ""3.0"" in /usr/local/lib/python3.5/dist-packages (from beautifulsoup4->-r requirements.txt (line 4)) (2.1)"
Requirement already satisfied, skipping upgrade: webencodings in /usr/local/lib/python3.5/dist-packages (from html5lib->-r requirements.txt (line 5)) (0.5.1)
Requirement already satisfied, skipping upgrade: six>=1.9 in /usr/local/lib/python3.5/dist-packages (from html5lib->-r requirements.txt (line 5)) (1.11.0)
"Building wheels for collected packages: predict
  Running setup.py bdist_wheel for predict: started
  Running setup.py bdist_wheel for predict: finished with status 'done'
  Stored in directory: /tmp/pip-ephem-wheel-cache-61w6exgg/wheels/35/24/16/37574d11bf9bde50616c67372a334f94fa8356bc7164af8ca3"
Successfully built predict
"Installing collected packages: predict
  Found existing installation: predict 1.0.0
    Uninstalling predict-1.0.0:
      Successfully uninstalled predict-1.0.0"
Successfully installed predict-1.0.0
You are using pip version 18.1, however version 20.3.4 is available.
You should consider upgrading via the 'pip install --upgrade pip' command.
Loading model.
model_info: {'hidden_dim': 200, 'vocab_size': 5000, 'embedding_dim': 32}
Done loading model.
"10.32.0.2 - - [12/Feb/2021:16:18:58 +0000] ""GET /ping HTTP/1.1"" 200 0 ""-"" ""AHC/2.0"""
"10.32.0.2 - - [12/Feb/2021:16:19:00 +0000] ""GET /ping HTTP/1.1"" 200 0 ""-"" ""AHC/2.0"""
Processing /opt/ml/code
Requirement already up-to-date: pandas in /usr/local/lib/python3.5/dist-packages (from -r requirements.txt (line 1)) (0.24.2)
Requirement already up-to-date: numpy in /usr/local/lib/python3.5/dist-packages (from -r requirements.txt (line 2)) (1.18.5)
Requirement already up-to-date: nltk in /usr/local/lib/python3.5/dist-packages (from -r requirements.txt (line 3)) (3.5)
Requirement already up-to-date: beautifulsoup4 in /usr/local/lib/python3.5/dist-packages (from -r requirements.txt (line 4)) (4.9.3)
Requirement already up-to-date: html5lib in /usr/local/lib/python3.5/dist-packages (from -r requirements.txt (line 5)) (1.1)
Requirement already satisfied, skipping upgrade: pytz>=2011k in /usr/local/lib/python3.5/dist-packages (from pandas->-r requirements.txt (line 1)) (2021.1)
Requirement already satisfied, skipping upgrade: python-dateutil>=2.5.0 in /usr/local/lib/python3.5/dist-packages (from pandas->-r requirements.txt (line 1)) (2.7.5)
Requirement already satisfied, skipping upgrade: regex in /usr/local/lib/python3.5/dist-packages (from nltk->-r requirements.txt (line 3)) (2020.11.13)
Requirement already satisfied, skipping upgrade: click in /usr/local/lib/python3.5/dist-packages (from nltk->-r requirements.txt (line 3)) (7.0)
Requirement already satisfied, skipping upgrade: tqdm in /usr/local/lib/python3.5/dist-packages (from nltk->-r requirements.txt (line 3)) (4.56.2)
Requirement already satisfied, skipping upgrade: joblib in /usr/local/lib/python3.5/dist-packages (from nltk->-r requirements.txt (line 3)) (0.14.1)
"Requirement already satisfied, skipping upgrade: soupsieve>1.2; python_version >= ""3.0"" in /usr/local/lib/python3.5/dist-packages (from beautifulsoup4->-r requirements.txt (line 4)) (2.1)"
Requirement already satisfied, skipping upgrade: six>=1.9 in /usr/local/lib/python3.5/dist-packages (from html5lib->-r requirements.txt (line 5)) (1.11.0)
Requirement already satisfied, skipping upgrade: webencodings in /usr/local/lib/python3.5/dist-packages (from html5lib->-r requirements.txt (line 5)) (0.5.1)
"Building wheels for collected packages: predict
  Running setup.py bdist_wheel for predict: started
  Running setup.py bdist_wheel for predict: finished with status 'done'
  Stored in directory: /tmp/pip-ephem-wheel-cache-3v133ejr/wheels/35/24/16/37574d11bf9bde50616c67372a334f94fa8356bc7164af8ca3"
Successfully built predict
"Installing collected packages: predict
  Found existing installation: predict 1.0.0
    Uninstalling predict-1.0.0:
      Successfully uninstalled predict-1.0.0"
Successfully installed predict-1.0.0
You are using pip version 18.1, however version 20.3.4 is available.
You should consider upgrading via the 'pip install --upgrade pip' command.
[2021-02-12 16:19:07 +0000] [28] [ERROR] Error handling request /ping
"Traceback (most recent call last):
  File ""/usr/local/lib/python3.5/dist-packages/sagemaker_containers/_modules.py"", line 248, in import_module
    module = importlib.import_module(name)
  File ""/usr/lib/python3.5/importlib/__init__.py"", line 126, in import_module
    return _bootstrap._gcd_import(name[level:], package, level)
  File ""<frozen importlib._bootstrap>"", line 986, in _gcd_import
  File ""<frozen importlib._bootstrap>"", line 969, in _find_and_load
  File ""<frozen importlib._bootstrap>"", line 958, in _find_and_load_unlocked
  File ""<frozen importlib._bootstrap>"", line 673, in _load_unlocked
  File ""<frozen importlib._bootstrap_external>"", line 665, in exec_module
  File ""<frozen importlib._bootstrap>"", line 222, in _call_with_frames_removed
  File ""/usr/local/lib/python3.5/dist-packages/predict.py"", line 7, in <module>
    import pandas as pd
  File ""/usr/local/lib/python3.5/dist-packages/pandas/__init__.py"", line 42, in <module>
    from pandas.core.api import *
  File ""/usr/local/lib/python3.5/dist-packages/pandas/core/api.py"", line 7, in <module>
    from pandas.core.arrays.integer import (
  File ""/usr/local/lib/python3.5/dist-packages/pandas/core/arrays/__init__.py"", line 2, in <module>
    from .base import (ExtensionArray,    # noqa
  File ""/usr/local/lib/python3.5/dist-packages/pandas/core/arrays/base.py"", line 21, in <module>
    from pandas.core import ops
  File ""/usr/local/lib/python3.5/dist-packages/pandas/core/ops.py"", line 17, in <module>
    import pandas.compat as compat"
"AttributeError: module 'pandas' has no attribute 'compat'
"
"During handling of the above exception, another exception occurred:
"
"Traceback (most recent call last):
  File ""/usr/local/lib/python3.5/dist-packages/gunicorn/workers/base_async.py"", line 56, in handle
    self.handle_request(listener_name, req, client, addr)
  File ""/usr/local/lib/python3.5/dist-packages/gunicorn/workers/ggevent.py"", line 160, in handle_request
    addr)
  File ""/usr/local/lib/python3.5/dist-packages/gunicorn/workers/base_async.py"", line 107, in handle_request
    respiter = self.wsgi(environ, resp.start_response)
  File ""/usr/local/lib/python3.5/dist-packages/sagemaker_pytorch_container/serving.py"", line 103, in main
    user_module = modules.import_module(serving_env.module_dir, serving_env.module_name)
  File ""/usr/local/lib/python3.5/dist-packages/sagemaker_containers/_modules.py"", line 253, in import_module
    six.reraise(_errors.ImportModuleError, _errors.ImportModuleError(e), sys.exc_info()[2])
  File ""/usr/local/lib/python3.5/dist-packages/six.py"", line 692, in reraise
    raise value.with_traceback(tb)
  File ""/usr/local/lib/python3.5/dist-packages/sagemaker_containers/_modules.py"", line 248, in import_module
    module = importlib.import_module(name)
  File ""/usr/lib/python3.5/importlib/__init__.py"", line 126, in import_module
    return _bootstrap._gcd_import(name[level:], package, level)
  File ""<frozen importlib._bootstrap>"", line 986, in _gcd_import
  File ""<frozen importlib._bootstrap>"", line 969, in _find_and_load
  File ""<frozen importlib._bootstrap>"", line 958, in _find_and_load_unlocked
  File ""<frozen importlib._bootstrap>"", line 673, in _load_unlocked
  File ""<frozen importlib._bootstrap_external>"", line 665, in exec_module
  File ""<frozen importlib._bootstrap>"", line 222, in _call_with_frames_removed
  File ""/usr/local/lib/python3.5/dist-packages/predict.py"", line 7, in <module>
    import pandas as pd
  File ""/usr/local/lib/python3.5/dist-packages/pandas/__init__.py"", line 42, in <module>
    from pandas.core.api import *
  File ""/usr/local/lib/python3.5/dist-packages/pandas/core/api.py"", line 7, in <module>
    from pandas.core.arrays.integer import (
  File ""/usr/local/lib/python3.5/dist-packages/pandas/core/arrays/__init__.py"", line 2, in <module>
    from .base import (ExtensionArray,    # noqa
  File ""/usr/local/lib/python3.5/dist-packages/pandas/core/arrays/base.py"", line 21, in <module>
    from pandas.core import ops
  File ""/usr/local/lib/python3.5/dist-packages/pandas/core/ops.py"", line 17, in <module>
    import pandas.compat as compat"
sagemaker_containers._errors.ImportModuleError: module 'pandas' has no attribute 'compat'
"10.32.0.2 - - [12/Feb/2021:16:19:07 +0000] ""GET /ping HTTP/1.1"" 500 141 ""-"" ""AHC/2.0"""
"10.32.0.2 - - [12/Feb/2021:16:19:10 +0000] ""GET /ping HTTP/1.1"" 200 0 ""-"" ""AHC/2.0"""
Processing /opt/ml/code
Requirement already up-to-date: pandas in /usr/local/lib/python3.5/dist-packages (from -r requirements.txt (line 1)) (0.24.2)
Requirement already up-to-date: numpy in /usr/local/lib/python3.5/dist-packages (from -r requirements.txt (line 2)) (1.18.5)
Requirement already up-to-date: nltk in /usr/local/lib/python3.5/dist-packages (from -r requirements.txt (line 3)) (3.5)
Requirement already up-to-date: beautifulsoup4 in /usr/local/lib/python3.5/dist-packages (from -r requirements.txt (line 4)) (4.9.3)
Requirement already up-to-date: html5lib in /usr/local/lib/python3.5/dist-packages (from -r requirements.txt (line 5)) (1.1)
Requirement already satisfied, skipping upgrade: pytz>=2011k in /usr/local/lib/python3.5/dist-packages (from pandas->-r requirements.txt (line 1)) (2021.1)
Requirement already satisfied, skipping upgrade: python-dateutil>=2.5.0 in /usr/local/lib/python3.5/dist-packages (from pandas->-r requirements.txt (line 1)) (2.7.5)
Requirement already satisfied, skipping upgrade: regex in /usr/local/lib/python3.5/dist-packages (from nltk->-r requirements.txt (line 3)) (2020.11.13)
Requirement already satisfied, skipping upgrade: joblib in /usr/local/lib/python3.5/dist-packages (from nltk->-r requirements.txt (line 3)) (0.14.1)
Requirement already satisfied, skipping upgrade: click in /usr/local/lib/python3.5/dist-packages (from nltk->-r requirements.txt (line 3)) (7.0)
Requirement already satisfied, skipping upgrade: tqdm in /usr/local/lib/python3.5/dist-packages (from nltk->-r requirements.txt (line 3)) (4.56.2)
"Requirement already satisfied, skipping upgrade: soupsieve>1.2; python_version >= ""3.0"" in /usr/local/lib/python3.5/dist-packages (from beautifulsoup4->-r requirements.txt (line 4)) (2.1)"
Requirement already satisfied, skipping upgrade: webencodings in /usr/local/lib/python3.5/dist-packages (from html5lib->-r requirements.txt (line 5)) (0.5.1)
Requirement already satisfied, skipping upgrade: six>=1.9 in /usr/local/lib/python3.5/dist-packages (from html5lib->-r requirements.txt (line 5)) (1.11.0)
"Building wheels for collected packages: predict
  Running setup.py bdist_wheel for predict: started
  Running setup.py bdist_wheel for predict: finished with status 'done'
  Stored in directory: /tmp/pip-ephem-wheel-cache-qvwkq6bx/wheels/35/24/16/37574d11bf9bde50616c67372a334f94fa8356bc7164af8ca3"
Successfully built predict
"Installing collected packages: predict
  Found existing installation: predict 1.0.0
    Uninstalling predict-1.0.0:
      Successfully uninstalled predict-1.0.0"
Successfully installed predict-1.0.0
You are using pip version 18.1, however version 20.3.4 is available.
You should consider upgrading via the 'pip install --upgrade pip' command.
[2021-02-12 16:19:17 +0000] [28] [ERROR] Error handling request /ping
"Traceback (most recent call last):
  File ""/usr/local/lib/python3.5/dist-packages/sagemaker_containers/_modules.py"", line 248, in import_module
    module = importlib.import_module(name)
  File ""/usr/lib/python3.5/importlib/__init__.py"", line 126, in import_module
    return _bootstrap._gcd_import(name[level:], package, level)
  File ""<frozen importlib._bootstrap>"", line 986, in _gcd_import
  File ""<frozen importlib._bootstrap>"", line 969, in _find_and_load
  File ""<frozen importlib._bootstrap>"", line 958, in _find_and_load_unlocked
  File ""<frozen importlib._bootstrap>"", line 673, in _load_unlocked
  File ""<frozen importlib._bootstrap_external>"", line 665, in exec_module
  File ""<frozen importlib._bootstrap>"", line 222, in _call_with_frames_removed
  File ""/usr/local/lib/python3.5/dist-packages/predict.py"", line 7, in <module>
    import pandas as pd
  File ""/usr/local/lib/python3.5/dist-packages/pandas/__init__.py"", line 42, in <module>
    from pandas.core.api import *
  File ""/usr/local/lib/python3.5/dist-packages/pandas/core/api.py"", line 7, in <module>
    from pandas.core.arrays.integer import (
  File ""/usr/local/lib/python3.5/dist-packages/pandas/core/arrays/__init__.py"", line 2, in <module>
    from .base import (ExtensionArray,    # noqa
  File ""/usr/local/lib/python3.5/dist-packages/pandas/core/arrays/base.py"", line 21, in <module>
    from pandas.core import ops"
"10.32.0.2 - - [12/Feb/2021:16:19:17 +0000] ""GET /ping HTTP/1.1"" 500 141 ""-"" ""AHC/2.0""
  File ""/usr/local/lib/python3.5/dist-packages/pandas/core/ops.py"", line 17, in <module>
    import pandas.compat as compat"
"AttributeError: module 'pandas' has no attribute 'compat'
"
"During handling of the above exception, another exception occurred:
"
"Traceback (most recent call last):
  File ""/usr/local/lib/python3.5/dist-packages/gunicorn/workers/base_async.py"", line 56, in handle
    self.handle_request(listener_name, req, client, addr)
  File ""/usr/local/lib/python3.5/dist-packages/gunicorn/workers/ggevent.py"", line 160, in handle_request
    addr)
  File ""/usr/local/lib/python3.5/dist-packages/gunicorn/workers/base_async.py"", line 107, in handle_request
    respiter = self.wsgi(environ, resp.start_response)
  File ""/usr/local/lib/python3.5/dist-packages/sagemaker_pytorch_container/serving.py"", line 103, in main
    user_module = modules.import_module(serving_env.module_dir, serving_env.module_name)
  File ""/usr/local/lib/python3.5/dist-packages/sagemaker_containers/_modules.py"", line 253, in import_module
    six.reraise(_errors.ImportModuleError, _errors.ImportModuleError(e), sys.exc_info()[2])
  File ""/usr/local/lib/python3.5/dist-packages/six.py"", line 692, in reraise
    raise value.with_traceback(tb)
  File ""/usr/local/lib/python3.5/dist-packages/sagemaker_containers/_modules.py"", line 248, in import_module
    module = importlib.import_module(name)
  File ""/usr/lib/python3.5/importlib/__init__.py"", line 126, in import_module
    return _bootstrap._gcd_import(name[level:], package, level)
  File ""<frozen importlib._bootstrap>"", line 986, in _gcd_import
  File ""<frozen importlib._bootstrap>"", line 969, in _find_and_load
  File ""<frozen importlib._bootstrap>"", line 958, in _find_and_load_unlocked
  File ""<frozen importlib._bootstrap>"", line 673, in _load_unlocked
  File ""<frozen importlib._bootstrap_external>"", line 665, in exec_module
  File ""<frozen importlib._bootstrap>"", line 222, in _call_with_frames_removed
  File ""/usr/local/lib/python3.5/dist-packages/predict.py"", line 7, in <module>
    import pandas as pd
  File ""/usr/local/lib/python3.5/dist-packages/pandas/__init__.py"", line 42, in <module>
    from pandas.core.api import *
  File ""/usr/local/lib/python3.5/dist-packages/pandas/core/api.py"", line 7, in <module>
    from pandas.core.arrays.integer import (
  File ""/usr/local/lib/python3.5/dist-packages/pandas/core/arrays/__init__.py"", line 2, in <module>
    from .base import (ExtensionArray,    # noqa
  File ""/usr/local/lib/python3.5/dist-packages/pandas/core/arrays/base.py"", line 21, in <module>
    from pandas.core import ops
  File ""/usr/local/lib/python3.5/dist-packages/pandas/core/ops.py"", line 17, in <module>
    import pandas.compat as compat"
sagemaker_containers._errors.ImportModuleError: module 'pandas' has no attribute 'compat'
"10.32.0.2 - - [12/Feb/2021:16:19:20 +0000] ""GET /ping HTTP/1.1"" 200 0 ""-"" ""AHC/2.0"""
"10.32.0.2 - - [12/Feb/2021:16:19:25 +0000] ""GET /ping HTTP/1.1"" 200 0 ""-"" ""AHC/2.0"""
"10.32.0.2 - - [12/Feb/2021:16:19:30 +0000] ""GET /ping HTTP/1.1"" 200 0 ""-"" ""AHC/2.0"""
"10.32.0.2 - - [12/Feb/2021:16:19:35 +0000] ""GET /ping HTTP/1.1"" 200 0 ""-"" ""AHC/2.0"""
Processing /opt/ml/code
Requirement already up-to-date: pandas in /usr/local/lib/python3.5/dist-packages (from -r requirements.txt (line 1)) (0.24.2)
Requirement already up-to-date: numpy in /usr/local/lib/python3.5/dist-packages (from -r requirements.txt (line 2)) (1.18.5)
Requirement already up-to-date: nltk in /usr/local/lib/python3.5/dist-packages (from -r requirements.txt (line 3)) (3.5)
Requirement already up-to-date: beautifulsoup4 in /usr/local/lib/python3.5/dist-packages (from -r requirements.txt (line 4)) (4.9.3)
Requirement already up-to-date: html5lib in /usr/local/lib/python3.5/dist-packages (from -r requirements.txt (line 5)) (1.1)
Requirement already satisfied, skipping upgrade: python-dateutil>=2.5.0 in /usr/local/lib/python3.5/dist-packages (from pandas->-r requirements.txt (line 1)) (2.7.5)
Requirement already satisfied, skipping upgrade: pytz>=2011k in /usr/local/lib/python3.5/dist-packages (from pandas->-r requirements.txt (line 1)) (2021.1)
Requirement already satisfied, skipping upgrade: regex in /usr/local/lib/python3.5/dist-packages (from nltk->-r requirements.txt (line 3)) (2020.11.13)
Requirement already satisfied, skipping upgrade: tqdm in /usr/local/lib/python3.5/dist-packages (from nltk->-r requirements.txt (line 3)) (4.56.2)
Requirement already satisfied, skipping upgrade: joblib in /usr/local/lib/python3.5/dist-packages (from nltk->-r requirements.txt (line 3)) (0.14.1)
Requirement already satisfied, skipping upgrade: click in /usr/local/lib/python3.5/dist-packages (from nltk->-r requirements.txt (line 3)) (7.0)
"Requirement already satisfied, skipping upgrade: soupsieve>1.2; python_version >= ""3.0"" in /usr/local/lib/python3.5/dist-packages (from beautifulsoup4->-r requirements.txt (line 4)) (2.1)"
Requirement already satisfied, skipping upgrade: six>=1.9 in /usr/local/lib/python3.5/dist-packages (from html5lib->-r requirements.txt (line 5)) (1.11.0)
Requirement already satisfied, skipping upgrade: webencodings in /usr/local/lib/python3.5/dist-packages (from html5lib->-r requirements.txt (line 5)) (0.5.1)
"Building wheels for collected packages: predict
  Running setup.py bdist_wheel for predict: started
  Running setup.py bdist_wheel for predict: finished with status 'done'
  Stored in directory: /tmp/pip-ephem-wheel-cache-r6vr1u3q/wheels/35/24/16/37574d11bf9bde50616c67372a334f94fa8356bc7164af8ca3"
Successfully built predict
"Installing collected packages: predict
  Found existing installation: predict 1.0.0
    Uninstalling predict-1.0.0:
      Successfully uninstalled predict-1.0.0"
Successfully installed predict-1.0.0
You are using pip version 18.1, however version 20.3.4 is available.
You should consider upgrading via the 'pip install --upgrade pip' command.
[2021-02-12 16:19:42 +0000] [27] [ERROR] Error handling request /ping
"Traceback (most recent call last):
  File ""/usr/local/lib/python3.5/dist-packages/sagemaker_containers/_modules.py"", line 248, in import_module
    module = importlib.import_module(name)
  File ""/usr/lib/python3.5/importlib/__init__.py"", line 126, in import_module
    return _bootstrap._gcd_import(name[level:], package, level)
  File ""<frozen importlib._bootstrap>"", line 986, in _gcd_import
  File ""<frozen importlib._bootstrap>"", line 969, in _find_and_load
  File ""<frozen importlib._bootstrap>"", line 958, in _find_and_load_unlocked
  File ""<frozen importlib._bootstrap>"", line 673, in _load_unlocked
  File ""<frozen importlib._bootstrap_external>"", line 665, in exec_module
  File ""<frozen importlib._bootstrap>"", line 222, in _call_with_frames_removed
  File ""/usr/local/lib/python3.5/dist-packages/predict.py"", line 7, in <module>
    import pandas as pd
  File ""/usr/local/lib/python3.5/dist-packages/pandas/__init__.py"", line 42, in <module>
    from pandas.core.api import *
  File ""/usr/local/lib/python3.5/dist-packages/pandas/core/api.py"", line 7, in <module>
    from pandas.core.arrays.integer import (
  File ""/usr/local/lib/python3.5/dist-packages/pandas/core/arrays/__init__.py"", line 2, in <module>
    from .base import (ExtensionArray,    # noqa
  File ""/usr/local/lib/python3.5/dist-packages/pandas/core/arrays/base.py"", line 21, in <module>
    from pandas.core import ops
  File ""/usr/local/lib/python3.5/dist-packages/pandas/core/ops.py"", line 17, in <module>
    import pandas.compat as compat"
"AttributeError: module 'pandas' has no attribute 'compat'
"
"During handling of the above exception, another exception occurred:
"
"Traceback (most recent call last):
  File ""/usr/local/lib/python3.5/dist-packages/gunicorn/workers/base_async.py"", line 56, in handle
    self.handle_request(listener_name, req, client, addr)
  File ""/usr/local/lib/python3.5/dist-packages/gunicorn/workers/ggevent.py"", line 160, in handle_request
    addr)
  File ""/usr/local/lib/python3.5/dist-packages/gunicorn/workers/base_async.py"", line 107, in handle_request
    respiter = self.wsgi(environ, resp.start_response)
  File ""/usr/local/lib/python3.5/dist-packages/sagemaker_pytorch_container/serving.py"", line 103, in main
    user_module = modules.import_module(serving_env.module_dir, serving_env.module_name)
  File ""/usr/local/lib/python3.5/dist-packages/sagemaker_containers/_modules.py"", line 253, in import_module
    six.reraise(_errors.ImportModuleError, _errors.ImportModuleError(e), sys.exc_info()[2])
  File ""/usr/local/lib/python3.5/dist-packages/six.py"", line 692, in reraise
    raise value.with_traceback(tb)
  File ""/usr/local/lib/python3.5/dist-packages/sagemaker_containers/_modules.py"", line 248, in import_module
    module = importlib.import_module(name)
  File ""/usr/lib/python3.5/importlib/__init__.py"", line 126, in import_module
    return _bootstrap._gcd_import(name[level:], package, level)
  File ""<frozen importlib._bootstrap>"", line 986, in _gcd_import"
"10.32.0.2 - - [12/Feb/2021:16:19:42 +0000] ""GET /ping HTTP/1.1"" 500 141 ""-"" ""AHC/2.0""
  File ""<frozen importlib._bootstrap>"", line 969, in _find_and_load
  File ""<frozen importlib._bootstrap>"", line 958, in _find_and_load_unlocked
  File ""<frozen importlib._bootstrap>"", line 673, in _load_unlocked
  File ""<frozen importlib._bootstrap_external>"", line 665, in exec_module
  File ""<frozen importlib._bootstrap>"", line 222, in _call_with_frames_removed
  File ""/usr/local/lib/python3.5/dist-packages/predict.py"", line 7, in <module>
    import pandas as pd
  File ""/usr/local/lib/python3.5/dist-packages/pandas/__init__.py"", line 42, in <module>
    from pandas.core.api import *
  File ""/usr/local/lib/python3.5/dist-packages/pandas/core/api.py"", line 7, in <module>
    from pandas.core.arrays.integer import (
  File ""/usr/local/lib/python3.5/dist-packages/pandas/core/arrays/__init__.py"", line 2, in <module>
    from .base import (ExtensionArray,    # noqa
  File ""/usr/local/lib/python3.5/dist-packages/pandas/core/arrays/base.py"", line 21, in <module>
    from pandas.core import ops
  File ""/usr/local/lib/python3.5/dist-packages/pandas/core/ops.py"", line 17, in <module>
    import pandas.compat as compat"
sagemaker_containers._errors.ImportModuleError: module 'pandas' has no attribute 'compat'
"10.32.0.2 - - [12/Feb/2021:16:19:45 +0000] ""GET /ping HTTP/1.1"" 200 0 ""-"" ""AHC/2.0"""
Processing /opt/ml/code
Requirement already up-to-date: pandas in /usr/local/lib/python3.5/dist-packages (from -r requirements.txt (line 1)) (0.24.2)
Requirement already up-to-date: numpy in /usr/local/lib/python3.5/dist-packages (from -r requirements.txt (line 2)) (1.18.5)
Requirement already up-to-date: nltk in /usr/local/lib/python3.5/dist-packages (from -r requirements.txt (line 3)) (3.5)
Requirement already up-to-date: beautifulsoup4 in /usr/local/lib/python3.5/dist-packages (from -r requirements.txt (line 4)) (4.9.3)
Requirement already up-to-date: html5lib in /usr/local/lib/python3.5/dist-packages (from -r requirements.txt (line 5)) (1.1)
Requirement already satisfied, skipping upgrade: python-dateutil>=2.5.0 in /usr/local/lib/python3.5/dist-packages (from pandas->-r requirements.txt (line 1)) (2.7.5)
Requirement already satisfied, skipping upgrade: pytz>=2011k in /usr/local/lib/python3.5/dist-packages (from pandas->-r requirements.txt (line 1)) (2021.1)
Requirement already satisfied, skipping upgrade: tqdm in /usr/local/lib/python3.5/dist-packages (from nltk->-r requirements.txt (line 3)) (4.56.2)
Requirement already satisfied, skipping upgrade: joblib in /usr/local/lib/python3.5/dist-packages (from nltk->-r requirements.txt (line 3)) (0.14.1)
Requirement already satisfied, skipping upgrade: click in /usr/local/lib/python3.5/dist-packages (from nltk->-r requirements.txt (line 3)) (7.0)
Requirement already satisfied, skipping upgrade: regex in /usr/local/lib/python3.5/dist-packages (from nltk->-r requirements.txt (line 3)) (2020.11.13)
"Requirement already satisfied, skipping upgrade: soupsieve>1.2; python_version >= ""3.0"" in /usr/local/lib/python3.5/dist-packages (from beautifulsoup4->-r requirements.txt (line 4)) (2.1)"
Requirement already satisfied, skipping upgrade: webencodings in /usr/local/lib/python3.5/dist-packages (from html5lib->-r requirements.txt (line 5)) (0.5.1)
Requirement already satisfied, skipping upgrade: six>=1.9 in /usr/local/lib/python3.5/dist-packages (from html5lib->-r requirements.txt (line 5)) (1.11.0)
"Building wheels for collected packages: predict
  Running setup.py bdist_wheel for predict: started
  Running setup.py bdist_wheel for predict: finished with status 'done'
  Stored in directory: /tmp/pip-ephem-wheel-cache-fnz8f2s3/wheels/35/24/16/37574d11bf9bde50616c67372a334f94fa8356bc7164af8ca3"
Successfully built predict
"Installing collected packages: predict
  Found existing installation: predict 1.0.0
    Uninstalling predict-1.0.0:
      Successfully uninstalled predict-1.0.0"
Successfully installed predict-1.0.0
You are using pip version 18.1, however version 20.3.4 is available.
You should consider upgrading via the 'pip install --upgrade pip' command.
[2021-02-12 16:19:48 +0000] [28] [ERROR] Error handling request /invocations
"Traceback (most recent call last):
  File ""/usr/local/lib/python3.5/dist-packages/sagemaker_containers/_modules.py"", line 248, in import_module
    module = importlib.import_module(name)
  File ""/usr/lib/python3.5/importlib/__init__.py"", line 126, in import_module
    return _bootstrap._gcd_import(name[level:], package, level)
  File ""<frozen importlib._bootstrap>"", line 986, in _gcd_import
  File ""<frozen importlib._bootstrap>"", line 969, in _find_and_load
  File ""<frozen importlib._bootstrap>"", line 958, in _find_and_load_unlocked
  File ""<frozen importlib._bootstrap>"", line 673, in _load_unlocked
  File ""<frozen importlib._bootstrap_external>"", line 665, in exec_module
  File ""<frozen importlib._bootstrap>"", line 222, in _call_with_frames_removed
  File ""/usr/local/lib/python3.5/dist-packages/predict.py"", line 7, in <module>
    import pandas as pd
  File ""/usr/local/lib/python3.5/dist-packages/pandas/__init__.py"", line 42, in <module>
    from pandas.core.api import *
  File ""/usr/local/lib/python3.5/dist-packages/pandas/core/api.py"", line 7, in <module>
    from pandas.core.arrays.integer import (
  File ""/usr/local/lib/python3.5/dist-packages/pandas/core/arrays/__init__.py"", line 2, in <module>
    from .base import (ExtensionArray,    # noqa
  File ""/usr/local/lib/python3.5/dist-packages/pandas/core/arrays/base.py"", line 21, in <module>
    from pandas.core import ops
  File ""/usr/local/lib/python3.5/dist-packages/pandas/core/ops.py"", line 17, in <module>
    import pandas.compat as compat"
"AttributeError: module 'pandas' has no attribute 'compat'
"
"During handling of the above exception, another exception occurred:
"
"Traceback (most recent call last):
  File ""/usr/local/lib/python3.5/dist-packages/gunicorn/workers/base_async.py"", line 56, in handle"
"10.32.0.2 - - [12/Feb/2021:16:19:48 +0000] ""POST /invocations HTTP/1.1"" 500 141 ""-"" ""AHC/2.0""
    self.handle_request(listener_name, req, client, addr)
  File ""/usr/local/lib/python3.5/dist-packages/gunicorn/workers/ggevent.py"", line 160, in handle_request
    addr)
  File ""/usr/local/lib/python3.5/dist-packages/gunicorn/workers/base_async.py"", line 107, in handle_request
    respiter = self.wsgi(environ, resp.start_response)
  File ""/usr/local/lib/python3.5/dist-packages/sagemaker_pytorch_container/serving.py"", line 103, in main
    user_module = modules.import_module(serving_env.module_dir, serving_env.module_name)
  File ""/usr/local/lib/python3.5/dist-packages/sagemaker_containers/_modules.py"", line 253, in import_module
    six.reraise(_errors.ImportModuleError, _errors.ImportModuleError(e), sys.exc_info()[2])
  File ""/usr/local/lib/python3.5/dist-packages/six.py"", line 692, in reraise
    raise value.with_traceback(tb)
  File ""/usr/local/lib/python3.5/dist-packages/sagemaker_containers/_modules.py"", line 248, in import_module
    module = importlib.import_module(name)
  File ""/usr/lib/python3.5/importlib/__init__.py"", line 126, in import_module
    return _bootstrap._gcd_import(name[level:], package, level)
  File ""<frozen importlib._bootstrap>"", line 986, in _gcd_import
  File ""<frozen importlib._bootstrap>"", line 969, in _find_and_load
  File ""<frozen importlib._bootstrap>"", line 958, in _find_and_load_unlocked
  File ""<frozen importlib._bootstrap>"", line 673, in _load_unlocked
  File ""<frozen importlib._bootstrap_external>"", line 665, in exec_module
  File ""<frozen importlib._bootstrap>"", line 222, in _call_with_frames_removed
  File ""/usr/local/lib/python3.5/dist-packages/predict.py"", line 7, in <module>
    import pandas as pd
  File ""/usr/local/lib/python3.5/dist-packages/pandas/__init__.py"", line 42, in <module>
    from pandas.core.api import *
  File ""/usr/local/lib/python3.5/dist-packages/pandas/core/api.py"", line 7, in <module>
    from pandas.core.arrays.integer import (
  File ""/usr/local/lib/python3.5/dist-packages/pandas/core/arrays/__init__.py"", line 2, in <module>
    from .base import (ExtensionArray,    # noqa
  File ""/usr/local/lib/python3.5/dist-packages/pandas/core/arrays/base.py"", line 21, in <module>
    from pandas.core import ops
  File ""/usr/local/lib/python3.5/dist-packages/pandas/core/ops.py"", line 17, in <module>
    import pandas.compat as compat"
sagemaker_containers._errors.ImportModuleError: module 'pandas' has no attribute 'compat'
"10.32.0.2 - - [12/Feb/2021:16:19:50 +0000] ""GET /ping HTTP/1.1"" 200 0 ""-"" ""AHC/2.0"""
Processing /opt/ml/code
Requirement already up-to-date: pandas in /usr/local/lib/python3.5/dist-packages (from -r requirements.txt (line 1)) (0.24.2)
Requirement already up-to-date: numpy in /usr/local/lib/python3.5/dist-packages (from -r requirements.txt (line 2)) (1.18.5)
Requirement already up-to-date: nltk in /usr/local/lib/python3.5/dist-packages (from -r requirements.txt (line 3)) (3.5)
Requirement already up-to-date: beautifulsoup4 in /usr/local/lib/python3.5/dist-packages (from -r requirements.txt (line 4)) (4.9.3)
Requirement already up-to-date: html5lib in /usr/local/lib/python3.5/dist-packages (from -r requirements.txt (line 5)) (1.1)
Requirement already satisfied, skipping upgrade: pytz>=2011k in /usr/local/lib/python3.5/dist-packages (from pandas->-r requirements.txt (line 1)) (2021.1)
Requirement already satisfied, skipping upgrade: python-dateutil>=2.5.0 in /usr/local/lib/python3.5/dist-packages (from pandas->-r requirements.txt (line 1)) (2.7.5)
Requirement already satisfied, skipping upgrade: joblib in /usr/local/lib/python3.5/dist-packages (from nltk->-r requirements.txt (line 3)) (0.14.1)
Requirement already satisfied, skipping upgrade: tqdm in /usr/local/lib/python3.5/dist-packages (from nltk->-r requirements.txt (line 3)) (4.56.2)
Requirement already satisfied, skipping upgrade: regex in /usr/local/lib/python3.5/dist-packages (from nltk->-r requirements.txt (line 3)) (2020.11.13)
Requirement already satisfied, skipping upgrade: click in /usr/local/lib/python3.5/dist-packages (from nltk->-r requirements.txt (line 3)) (7.0)
"Requirement already satisfied, skipping upgrade: soupsieve>1.2; python_version >= ""3.0"" in /usr/local/lib/python3.5/dist-packages (from beautifulsoup4->-r requirements.txt (line 4)) (2.1)"
Requirement already satisfied, skipping upgrade: webencodings in /usr/local/lib/python3.5/dist-packages (from html5lib->-r requirements.txt (line 5)) (0.5.1)
Requirement already satisfied, skipping upgrade: six>=1.9 in /usr/local/lib/python3.5/dist-packages (from html5lib->-r requirements.txt (line 5)) (1.11.0)
"Building wheels for collected packages: predict
  Running setup.py bdist_wheel for predict: started"
"  Running setup.py bdist_wheel for predict: finished with status 'done'
  Stored in directory: /tmp/pip-ephem-wheel-cache-rebhsdnx/wheels/35/24/16/37574d11bf9bde50616c67372a334f94fa8356bc7164af8ca3"
Successfully built predict
"Installing collected packages: predict
  Found existing installation: predict 1.0.0
    Uninstalling predict-1.0.0:
      Successfully uninstalled predict-1.0.0"
Successfully installed predict-1.0.0
You are using pip version 18.1, however version 20.3.4 is available.
You should consider upgrading via the 'pip install --upgrade pip' command.
[2021-02-12 16:19:57 +0000] [27] [ERROR] Error handling request /ping
"Traceback (most recent call last):
  File ""/usr/local/lib/python3.5/dist-packages/sagemaker_containers/_modules.py"", line 248, in import_module
    module = importlib.import_module(name)
  File ""/usr/lib/python3.5/importlib/__init__.py"", line 126, in import_module
    return _bootstrap._gcd_import(name[level:], package, level)
  File ""<frozen importlib._bootstrap>"", line 986, in _gcd_import
  File ""<frozen importlib._bootstrap>"", line 969, in _find_and_load
  File ""<frozen importlib._bootstrap>"", line 958, in _find_and_load_unlocked
  File ""<frozen importlib._bootstrap>"", line 673, in _load_unlocked
  File ""<frozen importlib._bootstrap_external>"", line 665, in exec_module
  File ""<frozen importlib._bootstrap>"", line 222, in _call_with_frames_removed
  File ""/usr/local/lib/python3.5/dist-packages/predict.py"", line 7, in <module>
    import pandas as pd
  File ""/usr/local/lib/python3.5/dist-packages/pandas/__init__.py"", line 42, in <module>
    from pandas.core.api import *
  File ""/usr/local/lib/python3.5/dist-packages/pandas/core/api.py"", line 7, in <module>
    from pandas.core.arrays.integer import (
  File ""/usr/local/lib/python3.5/dist-packages/pandas/core/arrays/__init__.py"", line 2, in <module>
    from .base import (ExtensionArray,    # noqa
  File ""/usr/local/lib/python3.5/dist-packages/pandas/core/arrays/base.py"", line 21, in <module>
    from pandas.core import ops
  File ""/usr/local/lib/python3.5/dist-packages/pandas/core/ops.py"", line 17, in <module>
    import pandas.compat as compat"
"AttributeError: module 'pandas' has no attribute 'compat'
"
"During handling of the above exception, another exception occurred:
"
"Traceback (most recent call last):
  File ""/usr/local/lib/python3.5/dist-packages/gunicorn/workers/base_async.py"", line 56, in handle
    self.handle_request(listener_name, req, client, addr)
  File ""/usr/local/lib/python3.5/dist-packages/gunicorn/workers/ggevent.py"", line 160, in handle_request
    addr)
  File ""/usr/local/lib/python3.5/dist-packages/gunicorn/workers/base_async.py"", line 107, in handle_request
    respiter = self.wsgi(environ, resp.start_response)
  File ""/usr/local/lib/python3.5/dist-packages/sagemaker_pytorch_container/serving.py"", line 103, in main
    user_module = modules.import_module(serving_env.module_dir, serving_env.module_name)
  File ""/usr/local/lib/python3.5/dist-packages/sagemaker_containers/_modules.py"", line 253, in import_module
    six.reraise(_errors.ImportModuleError, _errors.ImportModuleError(e), sys.exc_info()[2])
  File ""/usr/local/lib/python3.5/dist-packages/six.py"", line 692, in reraise
    raise value.with_traceback(tb)
  File ""/usr/local/lib/python3.5/dist-packages/sagemaker_containers/_modules.py"", line 248, in import_module
    module = importlib.import_module(name)
  File ""/usr/lib/python3.5/importlib/__init__.py"", line 126, in import_module
    return _bootstrap._gcd_import(name[level:], package, level)
  File ""<frozen importlib._bootstrap>"", line 986, in _gcd_import
  File ""<frozen importlib._bootstrap>"", line 969, in _find_and_load
  File ""<frozen importlib._bootstrap>"", line 958, in _find_and_load_unlocked
  File ""<frozen importlib._bootstrap>"", line 673, in _load_unlocked
  File ""<frozen importlib._bootstrap_external>"", line 665, in exec_module
  File ""<frozen importlib._bootstrap>"", line 222, in _call_with_frames_removed
  File ""/usr/local/lib/python3.5/dist-packages/predict.py"", line 7, in <module>
    import pandas as pd
  File ""/usr/local/lib/python3.5/dist-packages/pandas/__init__.py"", line 42, in <module>
    from pandas.core.api import *
  File ""/usr/local/lib/python3.5/dist-packages/pandas/core/api.py"", line 7, in <module>
    from pandas.core.arrays.integer import (
  File ""/usr/local/lib/python3.5/dist-packages/pandas/core/arrays/__init__.py"", line 2, in <module>
    from .base import (ExtensionArray,    # noqa
  File ""/usr/local/lib/python3.5/dist-packages/pandas/core/arrays/base.py"", line 21, in <module>
    from pandas.core import ops
  File ""/usr/local/lib/python3.5/dist-packages/pandas/core/ops.py"", line 17, in <module>
    import pandas.compat as compat"
sagemaker_containers._errors.ImportModuleError: module 'pandas' has no attribute 'compat'
"10.32.0.2 - - [12/Feb/2021:16:19:57 +0000] ""GET /ping HTTP/1.1"" 500 141 ""-"" ""AHC/2.0"""
Processing /opt/ml/code
Requirement already up-to-date: pandas in /usr/local/lib/python3.5/dist-packages (from -r requirements.txt (line 1)) (0.24.2)
Requirement already up-to-date: numpy in /usr/local/lib/python3.5/dist-packages (from -r requirements.txt (line 2)) (1.18.5)
Requirement already up-to-date: nltk in /usr/local/lib/python3.5/dist-packages (from -r requirements.txt (line 3)) (3.5)
Requirement already up-to-date: beautifulsoup4 in /usr/local/lib/python3.5/dist-packages (from -r requirements.txt (line 4)) (4.9.3)
Requirement already up-to-date: html5lib in /usr/local/lib/python3.5/dist-packages (from -r requirements.txt (line 5)) (1.1)
Requirement already satisfied, skipping upgrade: pytz>=2011k in /usr/local/lib/python3.5/dist-packages (from pandas->-r requirements.txt (line 1)) (2021.1)
Requirement already satisfied, skipping upgrade: python-dateutil>=2.5.0 in /usr/local/lib/python3.5/dist-packages (from pandas->-r requirements.txt (line 1)) (2.7.5)
Requirement already satisfied, skipping upgrade: click in /usr/local/lib/python3.5/dist-packages (from nltk->-r requirements.txt (line 3)) (7.0)
Requirement already satisfied, skipping upgrade: tqdm in /usr/local/lib/python3.5/dist-packages (from nltk->-r requirements.txt (line 3)) (4.56.2)
Requirement already satisfied, skipping upgrade: joblib in /usr/local/lib/python3.5/dist-packages (from nltk->-r requirements.txt (line 3)) (0.14.1)
Requirement already satisfied, skipping upgrade: regex in /usr/local/lib/python3.5/dist-packages (from nltk->-r requirements.txt (line 3)) (2020.11.13)
"Requirement already satisfied, skipping upgrade: soupsieve>1.2; python_version >= ""3.0"" in /usr/local/lib/python3.5/dist-packages (from beautifulsoup4->-r requirements.txt (line 4)) (2.1)"
Requirement already satisfied, skipping upgrade: webencodings in /usr/local/lib/python3.5/dist-packages (from html5lib->-r requirements.txt (line 5)) (0.5.1)
Requirement already satisfied, skipping upgrade: six>=1.9 in /usr/local/lib/python3.5/dist-packages (from html5lib->-r requirements.txt (line 5)) (1.11.0)
"Building wheels for collected packages: predict
  Running setup.py bdist_wheel for predict: started
  Running setup.py bdist_wheel for predict: finished with status 'done'
  Stored in directory: /tmp/pip-ephem-wheel-cache-36kn21vc/wheels/35/24/16/37574d11bf9bde50616c67372a334f94fa8356bc7164af8ca3"
Successfully built predict
"Installing collected packages: predict
  Found existing installation: predict 1.0.0
    Uninstalling predict-1.0.0:
      Successfully uninstalled predict-1.0.0"
Successfully installed predict-1.0.0
You are using pip version 18.1, however version 20.3.4 is available.
You should consider upgrading via the 'pip install --upgrade pip' command.
[2021-02-12 16:20:02 +0000] [28] [ERROR] Error handling request /ping
"Traceback (most recent call last):
  File ""/usr/local/lib/python3.5/dist-packages/sagemaker_containers/_modules.py"", line 248, in import_module
    module = importlib.import_module(name)
  File ""/usr/lib/python3.5/importlib/__init__.py"", line 126, in import_module
    return _bootstrap._gcd_import(name[level:], package, level)
  File ""<frozen importlib._bootstrap>"", line 986, in _gcd_import
  File ""<frozen importlib._bootstrap>"", line 969, in _find_and_load
  File ""<frozen importlib._bootstrap>"", line 958, in _find_and_load_unlocked
  File ""<frozen importlib._bootstrap>"", line 673, in _load_unlocked
  File ""<frozen importlib._bootstrap_external>"", line 665, in exec_module
  File ""<frozen importlib._bootstrap>"", line 222, in _call_with_frames_removed
  File ""/usr/local/lib/python3.5/dist-packages/predict.py"", line 7, in <module>
    import pandas as pd
  File ""/usr/local/lib/python3.5/dist-packages/pandas/__init__.py"", line 42, in <module>
    from pandas.core.api import *
  File ""/usr/local/lib/python3.5/dist-packages/pandas/core/api.py"", line 7, in <module>
    from pandas.core.arrays.integer import (
  File ""/usr/local/lib/python3.5/dist-packages/pandas/core/arrays/__init__.py"", line 2, in <module>
    from .base import (ExtensionArray,    # noqa
  File ""/usr/local/lib/python3.5/dist-packages/pandas/core/arrays/base.py"", line 21, in <module>
    from pandas.core import ops
  File ""/usr/local/lib/python3.5/dist-packages/pandas/core/ops.py"", line 17, in <module>
    import pandas.compat as compat"
"AttributeError: module 'pandas' has no attribute 'compat'
"
"During handling of the above exception, another exception occurred:
"
"Traceback (most recent call last):
  File ""/usr/local/lib/python3.5/dist-packages/gunicorn/workers/base_async.py"", line 56, in handle
    self.handle_request(listener_name, req, client, addr)
  File ""/usr/local/lib/python3.5/dist-packages/gunicorn/workers/ggevent.py"", line 160, in handle_request
    addr)
  File ""/usr/local/lib/python3.5/dist-packages/gunicorn/workers/base_async.py"", line 107, in handle_request
    respiter = self.wsgi(environ, resp.start_response)
  File ""/usr/local/lib/python3.5/dist-packages/sagemaker_pytorch_container/serving.py"", line 103, in main
    user_module = modules.import_module(serving_env.module_dir, serving_env.module_name)
  File ""/usr/local/lib/python3.5/dist-packages/sagemaker_containers/_modules.py"", line 253, in import_module
    six.reraise(_errors.ImportModuleError, _errors.ImportModuleError(e), sys.exc_info()[2])
  File ""/usr/local/lib/python3.5/dist-packages/six.py"", line 692, in reraise
    raise value.with_traceback(tb)
  File ""/usr/local/lib/python3.5/dist-packages/sagemaker_containers/_modules.py"", line 248, in import_module
    module = importlib.import_module(name)
  File ""/usr/lib/python3.5/importlib/__init__.py"", line 126, in import_module
    return _bootstrap._gcd_import(name[level:], package, level)
  File ""<frozen importlib._bootstrap>"", line 986, in _gcd_import
  File ""<frozen importlib._bootstrap>"", line 969, in _find_and_load
  File ""<frozen importlib._bootstrap>"", line 958, in _find_and_load_unlocked"
"10.32.0.2 - - [12/Feb/2021:16:20:02 +0000] ""GET /ping HTTP/1.1"" 500 141 ""-"" ""AHC/2.0""
  File ""<frozen importlib._bootstrap>"", line 673, in _load_unlocked
  File ""<frozen importlib._bootstrap_external>"", line 665, in exec_module
  File ""<frozen importlib._bootstrap>"", line 222, in _call_with_frames_removed
  File ""/usr/local/lib/python3.5/dist-packages/predict.py"", line 7, in <module>
    import pandas as pd
  File ""/usr/local/lib/python3.5/dist-packages/pandas/__init__.py"", line 42, in <module>
    from pandas.core.api import *
  File ""/usr/local/lib/python3.5/dist-packages/pandas/core/api.py"", line 7, in <module>
    from pandas.core.arrays.integer import (
  File ""/usr/local/lib/python3.5/dist-packages/pandas/core/arrays/__init__.py"", line 2, in <module>
    from .base import (ExtensionArray,    # noqa
  File ""/usr/local/lib/python3.5/dist-packages/pandas/core/arrays/base.py"", line 21, in <module>
    from pandas.core import ops
  File ""/usr/local/lib/python3.5/dist-packages/pandas/core/ops.py"", line 17, in <module>
    import pandas.compat as compat"
sagemaker_containers._errors.ImportModuleError: module 'pandas' has no attribute 'compat'
"10.32.0.2 - - [12/Feb/2021:16:20:05 +0000] ""GET /ping HTTP/1.1"" 200 0 ""-"" ""AHC/2.0"""
"10.32.0.2 - - [12/Feb/2021:16:20:10 +0000] ""GET /ping HTTP/1.1"" 200 0 ""-"" ""AHC/2.0"""
